Workbook
Name a_1: data!$H$39
Name a_2: data!$H$49
Name a_3: data!$H$60
Name a_4: data!$H$65
Name Alpha1_A: '[1]Ideal ICOMP_MH'!$B$309
Name Alpha1_B: '[1]Ideal ICOMP_MH'!$B$310
Name Alpha1_C: '[1]Ideal ICOMP_MH'!$B$311
Name Alpha2: '[1]Ideal ICOMP_MH'!$B$313
Name b_1: data!$H$40
Name b_2: data!$H$50
Name b_3: data!$H$61
Name b_4: data!$H$66
Name Beta: '[1]Ideal ICOMP_MH'!$B$314
Name c_1: data!$H$41
Name c_2: data!$H$51
Name c_3: data!$H$62
Name C_f1: data!$B$245
Name C_f2: data!$B$257
Name C_s1: data!$A$234
Name C_s2: data!$A$247
Name Cicomp: #REF!
Name Cicomp_maxrcmd: #REF!
Name Cicomp_minrcmd: #REF!
Name CICOMPmax_initial: data!$F$251
Name CICOMPmin_initial: data!$F$256
Name Cin: #REF!
Name Cin_initial: data!$F$227
Name Cin_rcmd: #REF!
Name Cisense: #REF!
Name Cisense_initial: data!$F$275
Name Coss: #REF!
Name Cout: #REF!
Name Cout_initial: data!$F$235
Name Cout_rcmd: #REF!
Name Cvcomp: #REF!
Name Cvcomp_p: #REF!
Name Cvcomp_p_initial: data!$F$270
Name Cvcomp_p_rcmd: #REF!
Name Cvcomp_rcmd: #REF!
Name CVCOMPinitial: data!$F$261
Name Cvins: #REF!
Name Cvins_actual: #REF!
Name Cvsense: #REF!
Name Cvsense_initial: data!$F$244
Name d_1: data!$H$42
Name d_2: data!$H$52
Name delta_Rfb1: #REF!
Name delta_Rfb2: #REF!
Name Dmax: #REF!
Name E_48f: data!$B$228
Name E_48s: data!$A$181
Name eff: #REF!
Name f_Iavg: #REF!
Name fiavg: #REF!
Name fline_max: #REF!
Name fline_min: #REF!
Name fline_nom: #REF!
Name fpole: #REF!
Name fPWM_PSpole: #REF!
Name fsw: #REF!

Sheet DF
C2: Tuning | D2: Origin | M2: =1/40000 -> 2.5e-05
B3: b0 | C3: 1e-05 | D3: 1e-05 | E3: ADC input (random) | F3: in0 | G3: in1 | H3: in2 | I3: out1 | J3: out2 | K3: Output (DF_result)
B4: b1 | C4: 2e-05 | D4: 2e-05 | E4: =(0.5+RAND())*500 -> 444.097 | F4: =E4 -> 444.097 | G4: 0 | H4: 0 | I4: 0 | J4: 0 | K4: =F4*$C$3+G4*$C$4+H4*$C$5+I4*$C$6+J4*$C$8 -> 0.00444097
B5: b2 | C5: 1e-05 | D5: 1e-05 | E5: =(0.5+RAND())*500 -> 470.12497 | F5: =E5 -> 470.12497 | G5: =F4 -> 444.097 | H5: 0 | I5: =K4 -> 0.00444097 | J5: 0 | K5: =F5*$C$3+G5*$C$4+H5*$C$5+I5*$C$6+J5*$C$8 -> 0.022409497
B6: a1 | C6: 1.987473 | D6: 1.987473 | E6: =(0.5+RAND())*500 -> 598.63151 | F6: =E6 -> 598.63151 | G6: =F5 -> 470.12497 | H6: =G5 -> 444.097 | I6: =K5 -> 0.022409497 | J6: =I5 -> 0.00444097 | K6: =F6*$C$3+G6*$C$4+H6*$C$5+I6*$C$6+J6*$C$8 -> 0.059982544
B7: a2 | C7: -0.987472 | D7: -0.987512 | E7: =(0.5+RAND())*500 -> 554.0154 | F7: =E7 -> 554.0154 | G7: =F6 -> 598.63151 | H7: =G6 -> 470.12497 | I7: =K6 -> 0.059982544 | J7: =I6 -> 0.022409497 | K7: =F7*$C$3+G7*$C$4+H7*$C$5+I7*$C$6+J7*$C$8 -> 0.11929807
C8: =C7-C11 -> -0.987512 | E8: =(0.5+RAND())*500 -> 308.53368 | F8: =E8 -> 308.53368 | G8: =F7 -> 554.0154 | H8: =G7 -> 598.63151 | I8: =K7 -> 0.11929807 | J8: =I7 -> 0.059982544 | K8: =F8*$C$3+G8*$C$4+H8*$C$5+I8*$C$6+J8*$C$8 -> 0.19802018
E9: =(0.5+RAND())*500 -> 730.48323 | F9: =E9 -> 730.48323 | G9: =F8 -> 308.53368 | H9: =G8 -> 554.0154 | I9: =K8 -> 0.19802018 | J9: =I8 -> 0.11929807 | K9: =F9*$C$3+G9*$C$4+H9*$C$5+I9*$C$6+J9*$C$8 -> 0.29476714
C10: =SUM(C3:C6,C8) -> 1.000001 | E10: =(0.5+RAND())*500 -> 744.78356 | F10: =E10 -> 744.78356 | G10: =F9 -> 730.48323 | H10: =G9 -> 308.53368 | I10: =K9 -> 0.29476714 | J10: =I9 -> 0.19802018 | K10: =F10*$C$3+G10*$C$4+H10*$C$5+I10*$C$6+J10*$C$8 -> 0.41543726
C11: =SUM(C3:C5) -> 4e-05 | E11: =(0.5+RAND())*500 -> 375.07992 | F11: =E11 -> 375.07992 | G11: =F10 -> 744.78356 | H11: =G10 -> 730.48323 | I11: =K10 -> 0.41543726 | J11: =I10 -> 0.29476714 | K11: =F11*$C$3+G11*$C$4+H11*$C$5+I11*$C$6+J11*$C$8 -> 0.56053556
E12: =(0.5+RAND())*500 -> 503.91374 | F12: =E12 -> 503.91374 | G12: =F11 -> 375.07992 | H12: =G11 -> 744.78356 | I12: =K11 -> 0.56053556 | J12: =I11 -> 0.41543726 | K12: =F12*$C$3+G12*$C$4+H12*$C$5+I12*$C$6+J12*$C$8 -> 0.72378858
E13: =(0.5+RAND())*500 -> 262.20583 | F13: =E13 -> 262.20583 | G13: =F12 -> 503.91374 | H13: =G12 -> 375.07992 | I13: =K12 -> 0.72378858 | J13: =I12 -> 0.56053556 | K13: =F13*$C$3+G13*$C$4+H13*$C$5+I13*$C$6+J13*$C$8 -> 0.9014258
E14: =(0.5+RAND())*500 -> 717.12169 | F14: =E14 -> 717.12169 | G14: =F13 -> 262.20583 | H14: =G13 -> 503.91374 | I14: =K13 -> 0.9014258 | J14: =I13 -> 0.72378858 | K14: =F14*$C$3+G14*$C$4+H14*$C$5+I14*$C$6+J14*$C$8 -> 1.094264
E15: =(0.5+RAND())*500 -> 616.23486 | F15: =E15 -> 616.23486 | G15: =F14 -> 717.12169 | H15: =G14 -> 262.20583 | I15: =K14 -> 1.094264 | J15: =I14 -> 0.9014258 | K15: =F15*$C$3+G15*$C$4+H15*$C$5+I15*$C$6+J15*$C$8 -> 1.3077782
E16: =(0.5+RAND())*500 -> 640.86181 | F16: =E16 -> 640.86181 | G16: =F15 -> 616.23486 | H16: =G15 -> 717.12169 | I16: =K15 -> 1.3077782 | J16: =I15 -> 1.094264 | K16: =F16*$C$3+G16*$C$4+H16*$C$5+I16*$C$6+J16*$C$8 -> 1.5444796
E17: =(0.5+RAND())*500 -> 632.99792 | F17: =E17 -> 632.99792 | G17: =F16 -> 640.86181 | H17: =G16 -> 616.23486 | I17: =K16 -> 1.5444796 | J17: =I16 -> 1.3077782 | K17: =F17*$C$3+G17*$C$4+H17*$C$5+I17*$C$6+J17*$C$8 -> 1.8034743
E18: =(0.5+RAND())*500 -> 667.16012 | F18: =E18 -> 667.16012 | G18: =F17 -> 632.99792 | H18: =G17 -> 640.86181 | I18: =K17 -> 1.8034743 | J18: =I17 -> 1.5444796 | K18: =F18*$C$3+G18*$C$4+H18*$C$5+I18*$C$6+J18*$C$8 -> 2.0849046
E19: =(0.5+RAND())*500 -> 504.06548 | F19: =E19 -> 504.06548 | G19: =F18 -> 667.16012 | H19: =G18 -> 632.99792 | I19: =K18 -> 2.0849046 | J19: =I18 -> 1.8034743 | K19: =F19*$C$3+G19*$C$4+H19*$C$5+I19*$C$6+J19*$C$8 -> 2.3874529
E20: =(0.5+RAND())*500 -> 408.81454 | F20: =E20 -> 408.81454 | G20: =F19 -> 504.06548 | H20: =G19 -> 667.16012 | I20: =K19 -> 2.3874529 | J20: =I19 -> 2.0849046 | K20: =F20*$C$3+G20*$C$4+H20*$C$5+I20*$C$6+J20*$C$8 -> 2.706971
E21: =(0.5+RAND())*500 -> 583.96872 | F21: =E21 -> 583.96872 | G21: =F20 -> 408.81454 | H21: =G20 -> 504.06548 | I21: =K20 -> 2.706971 | J21: =I20 -> 2.3874529 | K21: =F21*$C$3+G21*$C$4+H21*$C$5+I21*$C$6+J21*$C$8 -> 3.0414499
E22: =(0.5+RAND())*500 -> 310.91493 | F22: =E22 -> 310.91493 | G22: =F21 -> 583.96872 | H22: =G21 -> 408.81454 | I22: =K21 -> 3.0414499 | J22: =I21 -> 2.706971 | K22: =F22*$C$3+G22*$C$4+H22*$C$5+I22*$C$6+J22*$C$8 -> 3.3905099
E23: =(0.5+RAND())*500 -> 711.01058 | F23: =E23 -> 711.01058 | G23: =F22 -> 310.91493 | H23: =G22 -> 583.96872 | I23: =K22 -> 3.3905099 | J23: =I22 -> 3.0414499 | K23: =F23*$C$3+G23*$C$4+H23*$C$5+I23*$C$6+J23*$C$8 -> 3.7542468
... E10003: =(0.5+RAND())*500 -> 636.84392 | F10003: =E10003 -> 636.84392 | G10003: =F10002 -> 458.57636 | H10003: =G10002 -> 440.81849 | I10003: =K10002 -> 505.31798 | J10003: =I10002 -> 505.30469 | K10003: =F10003*$C$3+G10003*$C$4+H10003*$C$5+I10003*$C$6+J10003*$C$8 -> 505.33134

Sheet data
A2: Data for M1M2 vs VCOMP table
A4: VCOMP | B4: M1 | C4: M2 | D4: M1M2
A5: 0 | B5: =IF(A5<1,(0.068),IF(A5<2,(0.156*A5-0.088),IF(A5<4.5,(0.313*A5-0.401),IF(A5<=5,1.007,"VCOMP MUST BE < 5")))) -> 0.068 | C5: =IF(A5<=0.5,0,IF(A5<4.6,((fSW_target/65)*0.1223*(A5-0.5)^2),IF(A5<=5,((fSW_target/65)*2.056),"VCOMP MUST BE < 5"))) -> 0 | D5: =B5*C5 -> 0 | G5: mV factor | H5: =10^-3 -> 0.001
A6: =A5+0.05 -> 0.05 | B6: =IF(A6<1,(0.068),IF(A6<2,(0.156*A6-0.088),IF(A6<4.5,(0.313*A6-0.401),IF(A6<=5,1.007,"VCOMP MUST BE < 5")))) -> 0.068 | C6: =IF(A6<=0.5,0,IF(A6<4.6,((fSW_target/65)*0.1223*(A6-0.5)^2),IF(A6<=5,((fSW_target/65)*2.056),"VCOMP MUST BE < 5"))) -> 0 | D6: =B6*C6 -> 0 | G6: uF factor | H6: =(10^-6) -> 1e-06
A7: =A6+0.05 -> 0.1 | B7: =IF(A7<1,(0.068),IF(A7<2,(0.156*A7-0.088),IF(A7<4.5,(0.313*A7-0.401),IF(A7<=5,1.007,"VCOMP MUST BE < 5")))) -> 0.068 | C7: =IF(A7<=0.5,0,IF(A7<4.6,((fSW_target/65)*0.1223*(A7-0.5)^2),IF(A7<=5,((fSW_target/65)*2.056),"VCOMP MUST BE < 5"))) -> 0 | D7: =B7*C7 -> 0 | G7: kHz factor | H7: =10^3 -> 1000
A8: =A7+0.05 -> 0.15 | B8: =IF(A8<1,(0.068),IF(A8<2,(0.156*A8-0.088),IF(A8<4.5,(0.313*A8-0.401),IF(A8<=5,1.007,"VCOMP MUST BE < 5")))) -> 0.068 | C8: =IF(A8<=0.5,0,IF(A8<4.6,((fSW_target/65)*0.1223*(A8-0.5)^2),IF(A8<=5,((fSW_target/65)*2.056),"VCOMP MUST BE < 5"))) -> 0 | D8: =B8*C8 -> 0 | G8: mΩ factor | H8: =10^-3 -> 0.001
A9: =A8+0.05 -> 0.2 | B9: =IF(A9<1,(0.068),IF(A9<2,(0.156*A9-0.088),IF(A9<4.5,(0.313*A9-0.401),IF(A9<=5,1.007,"VCOMP MUST BE < 5")))) -> 0.068 | C9: =IF(A9<=0.5,0,IF(A9<4.6,((fSW_target/65)*0.1223*(A9-0.5)^2),IF(A9<=5,((fSW_target/65)*2.056),"VCOMP MUST BE < 5"))) -> 0 | D9: =B9*C9 -> 0 | G9: ms factor | H9: =10^-3 -> 0.001
A10: =A9+0.05 -> 0.25 | B10: =IF(A10<1,(0.068),IF(A10<2,(0.156*A10-0.088),IF(A10<4.5,(0.313*A10-0.401),IF(A10<=5,1.007,"VCOMP MUST BE < 5")))) -> 0.068 | C10: =IF(A10<=0.5,0,IF(A10<4.6,((fSW_target/65)*0.1223*(A10-0.5)^2),IF(A10<=5,((fSW_target/65)*2.056),"VCOMP MUST BE < 5"))) -> 0 | D10: =B10*C10 -> 0 | G10: mA factor | H10: =10^-3 -> 0.001
A11: =A10+0.05 -> 0.3 | B11: =IF(A11<1,(0.068),IF(A11<2,(0.156*A11-0.088),IF(A11<4.5,(0.313*A11-0.401),IF(A11<=5,1.007,"VCOMP MUST BE < 5")))) -> 0.068 | C11: =IF(A11<=0.5,0,IF(A11<4.6,((fSW_target/65)*0.1223*(A11-0.5)^2),IF(A11<=5,((fSW_target/65)*2.056),"VCOMP MUST BE < 5"))) -> 0 | D11: =B11*C11 -> 0 | G11: us factor | H11: =10^-6 -> 1e-06
A12: =A11+0.05 -> 0.35 | B12: =IF(A12<1,(0.068),IF(A12<2,(0.156*A12-0.088),IF(A12<4.5,(0.313*A12-0.401),IF(A12<=5,1.007,"VCOMP MUST BE < 5")))) -> 0.068 | C12: =IF(A12<=0.5,0,IF(A12<4.6,((fSW_target/65)*0.1223*(A12-0.5)^2),IF(A12<=5,((fSW_target/65)*2.056),"VCOMP MUST BE < 5"))) -> 0 | D12: =B12*C12 -> 0 | G12: uH factor | H12: =10^-6 -> 1e-06
A13: =A12+0.05 -> 0.4 | B13: =IF(A13<1,(0.068),IF(A13<2,(0.156*A13-0.088),IF(A13<4.5,(0.313*A13-0.401),IF(A13<=5,1.007,"VCOMP MUST BE < 5")))) -> 0.068 | C13: =IF(A13<=0.5,0,IF(A13<4.6,((fSW_target/65)*0.1223*(A13-0.5)^2),IF(A13<=5,((fSW_target/65)*2.056),"VCOMP MUST BE < 5"))) -> 0 | D13: =B13*C13 -> 0 | G13: ns factor | H13: =10^-9 -> 1e-09
A14: =A13+0.05 -> 0.45 | B14: =IF(A14<1,(0.068),IF(A14<2,(0.156*A14-0.088),IF(A14<4.5,(0.313*A14-0.401),IF(A14<=5,1.007,"VCOMP MUST BE < 5")))) -> 0.068 | C14: =IF(A14<=0.5,0,IF(A14<4.6,((fSW_target/65)*0.1223*(A14-0.5)^2),IF(A14<=5,((fSW_target/65)*2.056),"VCOMP MUST BE < 5"))) -> 0 | D14: =B14*C14 -> 0 | G14: mW factor | H14: =10^-3 -> 0.001
A15: =A14+0.05 -> 0.5 | B15: =IF(A15<1,(0.068),IF(A15<2,(0.156*A15-0.088),IF(A15<4.5,(0.313*A15-0.401),IF(A15<=5,1.007,"VCOMP MUST BE < 5")))) -> 0.068 | C15: =IF(A15<=0.5,0,IF(A15<4.6,((fSW_target/65)*0.1223*(A15-0.5)^2),IF(A15<=5,((fSW_target/65)*2.056),"VCOMP MUST BE < 5"))) -> 0 | D15: =B15*C15 -> 0 | G15: pF factor | H15: =10^-12 -> 1e-12
A16: =A15+0.05 -> 0.55 | B16: =IF(A16<1,(0.068),IF(A16<2,(0.156*A16-0.088),IF(A16<4.5,(0.313*A16-0.401),IF(A16<=5,1.007,"VCOMP MUST BE < 5")))) -> 0.068 | C16: =IF(A16<=0.5,0,IF(A16<4.6,((fSW_target/65)*0.1223*(A16-0.5)^2),IF(A16<=5,((fSW_target/65)*2.056),"VCOMP MUST BE < 5"))) -> #REF! | D16: =B16*C16 -> #REF! | G16: MHz factor | H16: =10^6 -> 1000000
A17: =A16+0.05 -> 0.6 | B17: =IF(A17<1,(0.068),IF(A17<2,(0.156*A17-0.088),IF(A17<4.5,(0.313*A17-0.401),IF(A17<=5,1.007,"VCOMP MUST BE < 5")))) -> 0.068 | C17: =IF(A17<=0.5,0,IF(A17<4.6,((fSW_target/65)*0.1223*(A17-0.5)^2),IF(A17<=5,((fSW_target/65)*2.056),"VCOMP MUST BE < 5"))) -> #REF! | D17: =B17*C17 -> #REF! | G17: uA factor | H17: =10^-6 -> 1e-06
A18: =A17+0.05 -> 0.65 | B18: =IF(A18<1,(0.068),IF(A18<2,(0.156*A18-0.088),IF(A18<4.5,(0.313*A18-0.401),IF(A18<=5,1.007,"VCOMP MUST BE < 5")))) -> 0.068 | C18: =IF(A18<=0.5,0,IF(A18<4.6,((fSW_target/65)*0.1223*(A18-0.5)^2),IF(A18<=5,((fSW_target/65)*2.056),"VCOMP MUST BE < 5"))) -> #REF! | D18: =B18*C18 -> #REF! | G18: kΩ factor | H18: =10^3 -> 1000
A19: =A18+0.05 -> 0.7 | B19: =IF(A19<1,(0.068),IF(A19<2,(0.156*A19-0.088),IF(A19<4.5,(0.313*A19-0.401),IF(A19<=5,1.007,"VCOMP MUST BE < 5")))) -> 0.068 | C19: =IF(A19<=0.5,0,IF(A19<4.6,((fSW_target/65)*0.1223*(A19-0.5)^2),IF(A19<=5,((fSW_target/65)*2.056),"VCOMP MUST BE < 5"))) -> #REF! | D19: =B19*C19 -> #REF! | G19: nC factor | H19: =10^-9 -> 1e-09
A20: =A19+0.05 -> 0.75 | B20: =IF(A20<1,(0.068),IF(A20<2,(0.156*A20-0.088),IF(A20<4.5,(0.313*A20-0.401),IF(A20<=5,1.007,"VCOMP MUST BE < 5")))) -> 0.068 | C20: =IF(A20<=0.5,0,IF(A20<4.6,((fSW_target/65)*0.1223*(A20-0.5)^2),IF(A20<=5,((fSW_target/65)*2.056),"VCOMP MUST BE < 5"))) -> #REF! | D20: =B20*C20 -> #REF! | G20: nF factor | H20: =10^-9 -> 1e-09
A21: =A20+0.05 -> 0.8 | B21: =IF(A21<1,(0.068),IF(A21<2,(0.156*A21-0.088),IF(A21<4.5,(0.313*A21-0.401),IF(A21<=5,1.007,"VCOMP MUST BE < 5")))) -> 0.068 | C21: =IF(A21<=0.5,0,IF(A21<4.6,((fSW_target/65)*0.1223*(A21-0.5)^2),IF(A21<=5,((fSW_target/65)*2.056),"VCOMP MUST BE < 5"))) -> #REF! | D21: =B21*C21 -> #REF! | G21: uC factor | H21: =10^-6 -> 1e-06
A22: =A21+0.05 -> 0.85 | B22: =IF(A22<1,(0.068),IF(A22<2,(0.156*A22-0.088),IF(A22<4.5,(0.313*A22-0.401),IF(A22<=5,1.007,"VCOMP MUST BE < 5")))) -> 0.068 | C22: =IF(A22<=0.5,0,IF(A22<4.6,((fSW_target/65)*0.1223*(A22-0.5)^2),IF(A22<=5,((fSW_target/65)*2.056),"VCOMP MUST BE < 5"))) -> #REF! | D22: =B22*C22 -> #REF! | G22: MΩ factor | H22: =10^6 -> 1000000
A23: =A22+0.05 -> 0.9 | B23: =IF(A23<1,(0.068),IF(A23<2,(0.156*A23-0.088),IF(A23<4.5,(0.313*A23-0.401),IF(A23<=5,1.007,"VCOMP MUST BE < 5")))) -> 0.068 | C23: =IF(A23<=0.5,0,IF(A23<4.6,((fSW_target/65)*0.1223*(A23-0.5)^2),IF(A23<=5,((fSW_target/65)*2.056),"VCOMP MUST BE < 5"))) -> #REF! | D23: =B23*C23 -> #REF! | G23: mH factor | H23: =10^-3 -> 0.001
A24: =A23+0.05 -> 0.95 | B24: =IF(A24<1,(0.068),IF(A24<2,(0.156*A24-0.088),IF(A24<4.5,(0.313*A24-0.401),IF(A24<=5,1.007,"VCOMP MUST BE < 5")))) -> 0.068 | C24: =IF(A24<=0.5,0,IF(A24<4.6,((fSW_target/65)*0.1223*(A24-0.5)^2),IF(A24<=5,((fSW_target/65)*2.056),"VCOMP MUST BE < 5"))) -> #REF! | D24: =B24*C24 -> #REF!
A25: =A24+0.05 -> 1 | B25: =IF(A25<1,(0.068),IF(A25<2,(0.156*A25-0.088),IF(A25<4.5,(0.313*A25-0.401),IF(A25<=5,1.007,"VCOMP MUST BE < 5")))) -> 0.068 | C25: =IF(A25<=0.5,0,IF(A25<4.6,((fSW_target/65)*0.1223*(A25-0.5)^2),IF(A25<=5,((fSW_target/65)*2.056),"VCOMP MUST BE < 5"))) -> #REF! | D25: =B25*C25 -> #REF!
A26: =A25+0.05 -> 1.05 | B26: =IF(A26<1,(0.068),IF(A26<2,(0.156*A26-0.088),IF(A26<4.5,(0.313*A26-0.401),IF(A26<=5,1.007,"VCOMP MUST BE < 5")))) -> 0.0758 | C26: =IF(A26<=0.5,0,IF(A26<4.6,((fSW_target/65)*0.1223*(A26-0.5)^2),IF(A26<=5,((fSW_target/65)*2.056),"VCOMP MUST BE < 5"))) -> #REF! | D26: =B26*C26 -> #REF!
A27: =A26+0.05 -> 1.1 | B27: =IF(A27<1,(0.068),IF(A27<2,(0.156*A27-0.088),IF(A27<4.5,(0.313*A27-0.401),IF(A27<=5,1.007,"VCOMP MUST BE < 5")))) -> 0.0836 | C27: =IF(A27<=0.5,0,IF(A27<4.6,((fSW_target/65)*0.1223*(A27-0.5)^2),IF(A27<=5,((fSW_target/65)*2.056),"VCOMP MUST BE < 5"))) -> #REF! | D27: =B27*C27 -> #REF!
A28: =A27+0.05 -> 1.15 | B28: =IF(A28<1,(0.068),IF(A28<2,(0.156*A28-0.088),IF(A28<4.5,(0.313*A28-0.401),IF(A28<=5,1.007,"VCOMP MUST BE < 5")))) -> 0.0914 | C28: =IF(A28<=0.5,0,IF(A28<4.6,((fSW_target/65)*0.1223*(A28-0.5)^2),IF(A28<=5,((fSW_target/65)*2.056),"VCOMP MUST BE < 5"))) -> #REF! | D28: =B28*C28 -> #REF!
A29: =A28+0.05 -> 1.2 | B29: =IF(A29<1,(0.068),IF(A29<2,(0.156*A29-0.088),IF(A29<4.5,(0.313*A29-0.401),IF(A29<=5,1.007,"VCOMP MUST BE < 5")))) -> 0.0992 | C29: =IF(A29<=0.5,0,IF(A29<4.6,((fSW_target/65)*0.1223*(A29-0.5)^2),IF(A29<=5,((fSW_target/65)*2.056),"VCOMP MUST BE < 5"))) -> #REF! | D29: =B29*C29 -> #REF!
A30: =A29+0.05 -> 1.25 | B30: =IF(A30<1,(0.068),IF(A30<2,(0.156*A30-0.088),IF(A30<4.5,(0.313*A30-0.401),IF(A30<=5,1.007,"VCOMP MUST BE < 5")))) -> 0.107 | C30: =IF(A30<=0.5,0,IF(A30<4.6,((fSW_target/65)*0.1223*(A30-0.5)^2),IF(A30<=5,((fSW_target/65)*2.056),"VCOMP MUST BE < 5"))) -> #REF! | D30: =B30*C30 -> #REF!
A31: =A30+0.05 -> 1.3 | B31: =IF(A31<1,(0.068),IF(A31<2,(0.156*A31-0.088),IF(A31<4.5,(0.313*A31-0.401),IF(A31<=5,1.007,"VCOMP MUST BE < 5")))) -> 0.1148 | C31: =IF(A31<=0.5,0,IF(A31<4.6,((fSW_target/65)*0.1223*(A31-0.5)^2),IF(A31<=5,((fSW_target/65)*2.056),"VCOMP MUST BE < 5"))) -> #REF! | D31: =B31*C31 -> #REF! | G31: K1 | H31: 7
A32: =A31+0.05 -> 1.35 | B32: =IF(A32<1,(0.068),IF(A32<2,(0.156*A32-0.088),IF(A32<4.5,(0.313*A32-0.401),IF(A32<=5,1.007,"VCOMP MUST BE < 5")))) -> 0.1226 | C32: =IF(A32<=0.5,0,IF(A32<4.6,((fSW_target/65)*0.1223*(A32-0.5)^2),IF(A32<=5,((fSW_target/65)*2.056),"VCOMP MUST BE < 5"))) -> #REF! | D32: =B32*C32 -> #REF! | G32: KFQ | H32: =1/(fsw*kHz) -> #REF!
A33: =A32+0.05 -> 1.4 | B33: =IF(A33<1,(0.068),IF(A33<2,(0.156*A33-0.088),IF(A33<4.5,(0.313*A33-0.401),IF(A33<=5,1.007,"VCOMP MUST BE < 5")))) -> 0.1304 | C33: =IF(A33<=0.5,0,IF(A33<4.6,((fSW_target/65)*0.1223*(A33-0.5)^2),IF(A33<=5,((fSW_target/65)*2.056),"VCOMP MUST BE < 5"))) -> #REF! | D33: =B33*C33 -> #REF! | G33: fTYP | H33: =65*kHz -> 65000 | J33: VINnom | K33: =(Vacin_min+Vacin_max)/2 -> #REF!
A34: =A33+0.05 -> 1.45 | B34: =IF(A34<1,(0.068),IF(A34<2,(0.156*A34-0.088),IF(A34<4.5,(0.313*A34-0.401),IF(A34<=5,1.007,"VCOMP MUST BE < 5")))) -> 0.1382 | C34: =IF(A34<=0.5,0,IF(A34<4.6,((fSW_target/65)*0.1223*(A34-0.5)^2),IF(A34<=5,((fSW_target/65)*2.056),"VCOMP MUST BE < 5"))) -> #REF! | D34: =B34*C34 -> #REF!
A35: =A34+0.05 -> 1.5 | B35: =IF(A35<1,(0.068),IF(A35<2,(0.156*A35-0.088),IF(A35<4.5,(0.313*A35-0.401),IF(A35<=5,1.007,"VCOMP MUST BE < 5")))) -> 0.146 | C35: =IF(A35<=0.5,0,IF(A35<4.6,((fSW_target/65)*0.1223*(A35-0.5)^2),IF(A35<=5,((fSW_target/65)*2.056),"VCOMP MUST BE < 5"))) -> #REF! | D35: =B35*C35 -> #REF! | G35: M1M2 | H35: =(Iout*(Vout_nom^2)*2.5*Rsense*K_1)/(eff*(VINnom^2)*K_FQ)*us -> #REF! | J35: M1M2 | K35: =(Iout*(Vout_nom^2)*2.5*Rsense*K_1)/(eff*(Vacin_nom^2)*K_FQ)*us -> #REF!
A36: =A35+0.05 -> 1.55 | B36: =IF(A36<1,(0.068),IF(A36<2,(0.156*A36-0.088),IF(A36<4.5,(0.313*A36-0.401),IF(A36<=5,1.007,"VCOMP MUST BE < 5")))) -> 0.1538 | C36: =IF(A36<=0.5,0,IF(A36<4.6,((fSW_target/65)*0.1223*(A36-0.5)^2),IF(A36<=5,((fSW_target/65)*2.056),"VCOMP MUST BE < 5"))) -> #REF! | D36: =B36*C36 -> #REF!
A37: =A36+0.05 -> 1.6 | B37: =IF(A37<1,(0.068),IF(A37<2,(0.156*A37-0.088),IF(A37<4.5,(0.313*A37-0.401),IF(A37<=5,1.007,"VCOMP MUST BE < 5")))) -> 0.1616 | C37: =IF(A37<=0.5,0,IF(A37<4.6,((fSW_target/65)*0.1223*(A37-0.5)^2),IF(A37<=5,((fSW_target/65)*2.056),"VCOMP MUST BE < 5"))) -> #REF! | D37: =B37*C37 -> #REF! | G37: VCOMP1 | H37: =(1*10^-9*(5*10^8*SQRT(fsw*kHz)+(1.09655978*10^10)*SQRT(ftyp)*SQRT(M1M2)))/SQRT(fsw*kHz) -> #REF! | J37: VCOMP1 | K37: =(1*10^-9*(5*10^8*SQRT(fsw*kHz)+(1.09655978*10^10)*SQRT(ftyp)*SQRT(M1M2)))/SQRT(fsw*kHz) -> #REF!
A38: =A37+0.05 -> 1.65 | B38: =IF(A38<1,(0.068),IF(A38<2,(0.156*A38-0.088),IF(A38<4.5,(0.313*A38-0.401),IF(A38<=5,1.007,"VCOMP MUST BE < 5")))) -> 0.1694 | C38: =IF(A38<=0.5,0,IF(A38<4.6,((fSW_target/65)*0.1223*(A38-0.5)^2),IF(A38<=5,((fSW_target/65)*2.056),"VCOMP MUST BE < 5"))) -> #REF! | D38: =B38*C38 -> #REF!
A39: =A38+0.05 -> 1.7 | B39: =IF(A39<1,(0.068),IF(A39<2,(0.156*A39-0.088),IF(A39<4.5,(0.313*A39-0.401),IF(A39<=5,1.007,"VCOMP MUST BE < 5")))) -> 0.1772 | C39: =IF(A39<=0.5,0,IF(A39<4.6,((fSW_target/65)*0.1223*(A39-0.5)^2),IF(A39<=5,((fSW_target/65)*2.056),"VCOMP MUST BE < 5"))) -> #REF! | D39: =B39*C39 -> #REF! | G39: a1 | H39: 0.156 | J39: a1 | K39: 0.156
A40: =A39+0.05 -> 1.75 | B40: =IF(A40<1,(0.068),IF(A40<2,(0.156*A40-0.088),IF(A40<4.5,(0.313*A40-0.401),IF(A40<=5,1.007,"VCOMP MUST BE < 5")))) -> 0.185 | C40: =IF(A40<=0.5,0,IF(A40<4.6,((fSW_target/65)*0.1223*(A40-0.5)^2),IF(A40<=5,((fSW_target/65)*2.056),"VCOMP MUST BE < 5"))) -> #REF! | D40: =B40*C40 -> #REF! | G40: b1 | H40: 0.088 | J40: b1 | K40: 0.088
A41: =A40+0.05 -> 1.8 | B41: =IF(A41<1,(0.068),IF(A41<2,(0.156*A41-0.088),IF(A41<4.5,(0.313*A41-0.401),IF(A41<=5,1.007,"VCOMP MUST BE < 5")))) -> 0.1928 | C41: =IF(A41<=0.5,0,IF(A41<4.6,((fSW_target/65)*0.1223*(A41-0.5)^2),IF(A41<=5,((fSW_target/65)*2.056),"VCOMP MUST BE < 5"))) -> #REF! | D41: =B41*C41 -> #REF! | G41: c1 | H41: 0.1223 | J41: c1 | K41: 0.1223
A42: =A41+0.05 -> 1.85 | B42: =IF(A42<1,(0.068),IF(A42<2,(0.156*A42-0.088),IF(A42<4.5,(0.313*A42-0.401),IF(A42<=5,1.007,"VCOMP MUST BE < 5")))) -> 0.2006 | C42: =IF(A42<=0.5,0,IF(A42<4.6,((fSW_target/65)*0.1223*(A42-0.5)^2),IF(A42<=5,((fSW_target/65)*2.056),"VCOMP MUST BE < 5"))) -> #REF! | D42: =B42*C42 -> #REF! | G42: d1 | H42: 0.5 | J42: d1 | K42: 0.5
...

Sheet VCOMP
A1: To Calculate VCOMP
A2: At User Selectable Line Voltage, Full Load | D2: At User Selectable Line Voltage, % of Load
A5: VLINE | B5: =Vline -> #REF! | D5: VLINE | E5: =Vline -> #REF! | G5: VCOMP as a function of Line voltage at full load
A6: K1 | B6: 7 | D6: Percent Load | E6: =percent_load/100 -> #REF! | G6: VLINE | H6: M1M2 | I6: VCOMP1 | J6: K1V2 | K6: K2V2 | L6: K3V2 | M6: K4V2 | N6: VCOMP2 | O6: K1V3 | P6: K2V3 | Q6: K3V3 | R6: K4V3 | S6: K5V3 | T6: VCOMP3 | U6: VCOMP4 | V6: VCOMP5 | W6: VCOMP | X6: IAC RMS | Y6: ISENSE_Pk | Z6: ICOMP
A7: KFQ | B7: =1/(fsw*kHz) -> #REF! | D7: K1 | E7: 7 | G7: =Vacin_min -> #REF! | H7: =(Iout*(Vout_nom^2)*2.5*Rsense*K_1)/(eff*(G7^2)*K_FQ)*us -> #REF! | I7: =(1*10^-9*(5*10^8*SQRT(fsw*kHz)+(1.09655978*10^10)*SQRT(ftyp)*SQRT(H7)))/SQRT(fsw*kHz) -> #REF! | J7: =(b_1^3/(27*a_1^3))-(d_1^3/27)+SQRT((ftyp)^2*H7^2/(4*a_1^2*c_1^2*(fsw*kHz)^2))+(b_1^3*(ftyp)*H7/(27*a_1^4*c_1*(fsw*kHz))-(d_1^3*(ftyp)*H7/(27*a_1*c_1*(fsw*kHz)))+(b_1*d_1^2*(ftyp)*H7/(9*a_1^2*c_1*(fsw*kHz)))-(b_1^2*d_1*(ftyp)*H7/(9*a_1^3*c_1*(fsw*kHz)))) -> #REF! | K7: =(b_1*d_1^2/(9*a_1))-(b_1^2*d_1/(9*a_1^2))+(ftyp*H7/(2*a_1*c_1*fsw*kHz)) -> #REF! | L7: =(d_1^2/9)+(b_1^2/(9*a_1^2))-(2*b_1*d_1/(9*a_1)) -> 0.00045657097 | M7: =((b_1*c_1*fsw*kHz)+(2*a_1*c_1*d_1*fsw*kHz))/(3*a_1*c_1*fsw*kHz) -> #REF! | N7: =(J7+K7)^(1/3)+(L7/(J7^(1/3)))+M7 -> #REF! | O7: =(b_2^3/(27*a_2^3))-(d_2^3/27) -> 0.073252235 | P7: =(ftyp^2*H7^2/(4*a_2^2*c_2^2*(fsw*kHz)^2))+(b_2^3*ftyp*H7/(27*a_2^4*c_2*(fsw*kHz)))-(d_2^3*ftyp*H7/(27*a_2*c_2*(fsw*kHz)))+(b_2*d_2^2*ftyp*H7/(9*a_2^2*c_2*(fsw*kHz)))-(b_2^2*d_2*ftyp*H7/(9*a_2^3*c_2*(fsw*kHz))) -> #REF! | Q7: =(b_2*d_2^2/(9*a_2))-(b_2^2*d_2/(9*a_2^2))+(ftyp*H7/(2*a_2*c_2*(fsw*kHz))) -> #REF! | R7: =(d_2^2/9)+(b_2^2/(9*a_2^2))-(2*b_2*d_2/(9*a_2)) -> 0.067799508 | S7: =(b_2*c_2*(fsw*kHz)+2*a_2*c_2*d_2*(fsw*kHz))/(3*a_2*c_2*(fsw*kHz)) -> #REF! | T7: =((O7+SQRT(P7)+Q7)^(1/3))+(R7/((O7+SQRT(P7)+Q7)^(1/3)))+S7 -> #REF! | U7: =c_3+(SQRT(ftyp)*SQRT(H7)/(SQRT(a_3)*SQRT(b_3)*SQRT(fsw*kHz))) -> #REF! | V7: =(a_4*(fsw*kHz)*b_4/ftyp) -> #REF! | W7: =IF(I7>=0.5,IF(I7<1,I7,IF(N7>=1,IF(N7<2,N7,IF(T7>=2,IF(T7<4.5,T7,IF(U7>=4.5,IF(U7<4.6,U7,V7)))))))) -> #REF! | X7: =Pin_max/G7 -> #REF! | Y7: =-X7*Rsense*1.414 -> #REF! | Z7: =MIN(6,MAX(0.5,Beta*G*($Y7-Voff_trim)/(MAX(0,MIN(4.5,W7)-Alpha1_A)+MAX(0,MIN(4.5,W7)-Alpha1_B)-Alpha1_C)+Alpha2)) -> #REF!
A8: fTYP | B8: =65*kHz -> 65000 | D8: KFQ | E8: =1/(fsw*kHz) -> #REF! | G8: =G7+1 -> #REF! | H8: =(Iout*(Vout_nom^2)*2.5*Rsense*K_1)/(eff*(G8^2)*K_FQ)*us -> #REF! | I8: =(1*10^-9*(5*10^8*SQRT(fsw*kHz)+(1.09655978*10^10)*SQRT(ftyp)*SQRT(H8)))/SQRT(fsw*kHz) -> #REF! | J8: =(b_1^3/(27*a_1^3))-(d_1^3/27)+SQRT((ftyp)^2*H8^2/(4*a_1^2*c_1^2*(fsw*kHz)^2))+(b_1^3*(ftyp)*H8/(27*a_1^4*c_1*(fsw*kHz))-(d_1^3*(ftyp)*H8/(27*a_1*c_1*(fsw*kHz)))+(b_1*d_1^2*(ftyp)*H8/(9*a_1^2*c_1*(fsw*kHz)))-(b_1^2*d_1*(ftyp)*H8/(9*a_1^3*c_1*(fsw*kHz)))) -> #REF! | K8: =(b_1*d_1^2/(9*a_1))-(b_1^2*d_1/(9*a_1^2))+(ftyp*H8/(2*a_1*c_1*fsw*kHz)) -> #REF! | L8: =(d_1^2/9)+(b_1^2/(9*a_1^2))-(2*b_1*d_1/(9*a_1)) -> 0.00045657097 | M8: =((b_1*c_1*fsw*kHz)+(2*a_1*c_1*d_1*fsw*kHz))/(3*a_1*c_1*fsw*kHz) -> #REF! | N8: =(J8+K8)^(1/3)+(L8/(J8^(1/3)))+M8 -> #REF! | O8: =(b_2^3/(27*a_2^3))-(d_2^3/27) -> 0.073252235 | P8: =(ftyp^2*H8^2/(4*a_2^2*c_2^2*(fsw*kHz)^2))+(b_2^3*ftyp*H8/(27*a_2^4*c_2*(fsw*kHz)))-(d_2^3*ftyp*H8/(27*a_2*c_2*(fsw*kHz)))+(b_2*d_2^2*ftyp*H8/(9*a_2^2*c_2*(fsw*kHz)))-(b_2^2*d_2*ftyp*H8/(9*a_2^3*c_2*(fsw*kHz))) -> #REF! | Q8: =(b_2*d_2^2/(9*a_2))-(b_2^2*d_2/(9*a_2^2))+(ftyp*H8/(2*a_2*c_2*(fsw*kHz))) -> #REF! | R8: =(d_2^2/9)+(b_2^2/(9*a_2^2))-(2*b_2*d_2/(9*a_2)) -> 0.067799508 | S8: =(b_2*c_2*(fsw*kHz)+2*a_2*c_2*d_2*(fsw*kHz))/(3*a_2*c_2*(fsw*kHz)) -> #REF! | T8: =((O8+SQRT(P8)+Q8)^(1/3))+(R8/((O8+SQRT(P8)+Q8)^(1/3)))+S8 -> #REF! | U8: =c_3+(SQRT(ftyp)*SQRT(H8)/(SQRT(a_3)*SQRT(b_3)*SQRT(fsw*kHz))) -> #REF! | V8: =(a_4*(fsw*kHz)*b_4/ftyp) -> #REF! | W8: =IF(I8>=0.5,IF(I8<1,I8,IF(N8>=1,IF(N8<2,N8,IF(T8>=2,IF(T8<4.5,T8,IF(U8>=4.5,IF(U8<4.6,U8,V8)))))))) -> #REF! | X8: =Pin_max/G8 -> #REF! | Y8: =-X8*Rsense*1.414 -> #REF! | Z8: =MIN(6,MAX(0.5,Beta*G*($Y8-Voff_trim)/(MAX(0,MIN(4.5,W8)-Alpha1_A)+MAX(0,MIN(4.5,W8)-Alpha1_B)-Alpha1_C)+Alpha2)) -> #REF!
D9: fTYP | E9: =65*kHz -> 65000 | G9: =G8+1 -> #REF! | H9: =(Iout*(Vout_nom^2)*2.5*Rsense*K_1)/(eff*(G9^2)*K_FQ)*us -> #REF! | I9: =(1*10^-9*(5*10^8*SQRT(fsw*kHz)+(1.09655978*10^10)*SQRT(ftyp)*SQRT(H9)))/SQRT(fsw*kHz) -> #REF! | J9: =(b_1^3/(27*a_1^3))-(d_1^3/27)+SQRT((ftyp)^2*H9^2/(4*a_1^2*c_1^2*(fsw*kHz)^2))+(b_1^3*(ftyp)*H9/(27*a_1^4*c_1*(fsw*kHz))-(d_1^3*(ftyp)*H9/(27*a_1*c_1*(fsw*kHz)))+(b_1*d_1^2*(ftyp)*H9/(9*a_1^2*c_1*(fsw*kHz)))-(b_1^2*d_1*(ftyp)*H9/(9*a_1^3*c_1*(fsw*kHz)))) -> #REF! | K9: =(b_1*d_1^2/(9*a_1))-(b_1^2*d_1/(9*a_1^2))+(ftyp*H9/(2*a_1*c_1*fsw*kHz)) -> #REF! | L9: =(d_1^2/9)+(b_1^2/(9*a_1^2))-(2*b_1*d_1/(9*a_1)) -> 0.00045657097 | M9: =((b_1*c_1*fsw*kHz)+(2*a_1*c_1*d_1*fsw*kHz))/(3*a_1*c_1*fsw*kHz) -> #REF! | N9: =(J9+K9)^(1/3)+(L9/(J9^(1/3)))+M9 -> #REF! | O9: =(b_2^3/(27*a_2^3))-(d_2^3/27) -> 0.073252235 | P9: =(ftyp^2*H9^2/(4*a_2^2*c_2^2*(fsw*kHz)^2))+(b_2^3*ftyp*H9/(27*a_2^4*c_2*(fsw*kHz)))-(d_2^3*ftyp*H9/(27*a_2*c_2*(fsw*kHz)))+(b_2*d_2^2*ftyp*H9/(9*a_2^2*c_2*(fsw*kHz)))-(b_2^2*d_2*ftyp*H9/(9*a_2^3*c_2*(fsw*kHz))) -> #REF! | Q9: =(b_2*d_2^2/(9*a_2))-(b_2^2*d_2/(9*a_2^2))+(ftyp*H9/(2*a_2*c_2*(fsw*kHz))) -> #REF! | R9: =(d_2^2/9)+(b_2^2/(9*a_2^2))-(2*b_2*d_2/(9*a_2)) -> 0.067799508 | S9: =(b_2*c_2*(fsw*kHz)+2*a_2*c_2*d_2*(fsw*kHz))/(3*a_2*c_2*(fsw*kHz)) -> #REF! | T9: =((O9+SQRT(P9)+Q9)^(1/3))+(R9/((O9+SQRT(P9)+Q9)^(1/3)))+S9 -> #REF! | U9: =c_3+(SQRT(ftyp)*SQRT(H9)/(SQRT(a_3)*SQRT(b_3)*SQRT(fsw*kHz))) -> #REF! | V9: =(a_4*(fsw*kHz)*b_4/ftyp) -> #REF! | W9: =IF(I9>=0.5,IF(I9<1,I9,IF(N9>=1,IF(N9<2,N9,IF(T9>=2,IF(T9<4.5,T9,IF(U9>=4.5,IF(U9<4.6,U9,V9)))))))) -> #REF! | X9: =Pin_max/G9 -> #REF! | Y9: =-X9*Rsense*1.414 -> #REF! | Z9: =MIN(6,MAX(0.5,Beta*G*($Y9-Voff_trim)/(MAX(0,MIN(4.5,W9)-Alpha1_A)+MAX(0,MIN(4.5,W9)-Alpha1_B)-Alpha1_C)+Alpha2)) -> #REF!
A10: M1M2 | B10: =(Iout*(Vout_nom^2)*2.5*Rsense*K_1)/(eff*(B5^2)*K_FQ)*us -> #REF! | G10: =G9+1 -> #REF! | H10: =(Iout*(Vout_nom^2)*2.5*Rsense*K_1)/(eff*(G10^2)*K_FQ)*us -> #REF! | I10: =(1*10^-9*(5*10^8*SQRT(fsw*kHz)+(1.09655978*10^10)*SQRT(ftyp)*SQRT(H10)))/SQRT(fsw*kHz) -> #REF! | J10: =(b_1^3/(27*a_1^3))-(d_1^3/27)+SQRT((ftyp)^2*H10^2/(4*a_1^2*c_1^2*(fsw*kHz)^2))+(b_1^3*(ftyp)*H10/(27*a_1^4*c_1*(fsw*kHz))-(d_1^3*(ftyp)*H10/(27*a_1*c_1*(fsw*kHz)))+(b_1*d_1^2*(ftyp)*H10/(9*a_1^2*c_1*(fsw*kHz)))-(b_1^2*d_1*(ftyp)*H10/(9*a_1^3*c_1*(fsw*kHz)))) -> #REF! | K10: =(b_1*d_1^2/(9*a_1))-(b_1^2*d_1/(9*a_1^2))+(ftyp*H10/(2*a_1*c_1*fsw*kHz)) -> #REF! | L10: =(d_1^2/9)+(b_1^2/(9*a_1^2))-(2*b_1*d_1/(9*a_1)) -> 0.00045657097 | M10: =((b_1*c_1*fsw*kHz)+(2*a_1*c_1*d_1*fsw*kHz))/(3*a_1*c_1*fsw*kHz) -> #REF! | N10: =(J10+K10)^(1/3)+(L10/(J10^(1/3)))+M10 -> #REF! | O10: =(b_2^3/(27*a_2^3))-(d_2^3/27) -> 0.073252235 | P10: =(ftyp^2*H10^2/(4*a_2^2*c_2^2*(fsw*kHz)^2))+(b_2^3*ftyp*H10/(27*a_2^4*c_2*(fsw*kHz)))-(d_2^3*ftyp*H10/(27*a_2*c_2*(fsw*kHz)))+(b_2*d_2^2*ftyp*H10/(9*a_2^2*c_2*(fsw*kHz)))-(b_2^2*d_2*ftyp*H10/(9*a_2^3*c_2*(fsw*kHz))) -> #REF! | Q10: =(b_2*d_2^2/(9*a_2))-(b_2^2*d_2/(9*a_2^2))+(ftyp*H10/(2*a_2*c_2*(fsw*kHz))) -> #REF! | R10: =(d_2^2/9)+(b_2^2/(9*a_2^2))-(2*b_2*d_2/(9*a_2)) -> 0.067799508 | S10: =(b_2*c_2*(fsw*kHz)+2*a_2*c_2*d_2*(fsw*kHz))/(3*a_2*c_2*(fsw*kHz)) -> #REF! | T10: =((O10+SQRT(P10)+Q10)^(1/3))+(R10/((O10+SQRT(P10)+Q10)^(1/3)))+S10 -> #REF! | U10: =c_3+(SQRT(ftyp)*SQRT(H10)/(SQRT(a_3)*SQRT(b_3)*SQRT(fsw*kHz))) -> #REF! | V10: =(a_4*(fsw*kHz)*b_4/ftyp) -> #REF! | W10: =IF(I10>=0.5,IF(I10<1,I10,IF(N10>=1,IF(N10<2,N10,IF(T10>=2,IF(T10<4.5,T10,IF(U10>=4.5,IF(U10<4.6,U10,V10)))))))) -> #REF! | X10: =Pin_max/G10 -> #REF! | Y10: =-X10*Rsense*1.414 -> #REF! | Z10: =MIN(6,MAX(0.5,Beta*G*($Y10-Voff_trim)/(MAX(0,MIN(4.5,W10)-Alpha1_A)+MAX(0,MIN(4.5,W10)-Alpha1_B)-Alpha1_C)+Alpha2)) -> #REF!
D11: M1M2 | E11: =((E6*Iout)*(Vout_nom^2)*2.5*Rsense*K_1)/(eff*(E5^2)*K_FQ)*us -> #REF! | G11: =G10+1 -> #REF! | H11: =(Iout*(Vout_nom^2)*2.5*Rsense*K_1)/(eff*(G11^2)*K_FQ)*us -> #REF! | I11: =(1*10^-9*(5*10^8*SQRT(fsw*kHz)+(1.09655978*10^10)*SQRT(ftyp)*SQRT(H11)))/SQRT(fsw*kHz) -> #REF! | J11: =(b_1^3/(27*a_1^3))-(d_1^3/27)+SQRT((ftyp)^2*H11^2/(4*a_1^2*c_1^2*(fsw*kHz)^2))+(b_1^3*(ftyp)*H11/(27*a_1^4*c_1*(fsw*kHz))-(d_1^3*(ftyp)*H11/(27*a_1*c_1*(fsw*kHz)))+(b_1*d_1^2*(ftyp)*H11/(9*a_1^2*c_1*(fsw*kHz)))-(b_1^2*d_1*(ftyp)*H11/(9*a_1^3*c_1*(fsw*kHz)))) -> #REF! | K11: =(b_1*d_1^2/(9*a_1))-(b_1^2*d_1/(9*a_1^2))+(ftyp*H11/(2*a_1*c_1*fsw*kHz)) -> #REF! | L11: =(d_1^2/9)+(b_1^2/(9*a_1^2))-(2*b_1*d_1/(9*a_1)) -> 0.00045657097 | M11: =((b_1*c_1*fsw*kHz)+(2*a_1*c_1*d_1*fsw*kHz))/(3*a_1*c_1*fsw*kHz) -> #REF! | N11: =(J11+K11)^(1/3)+(L11/(J11^(1/3)))+M11 -> #REF! | O11: =(b_2^3/(27*a_2^3))-(d_2^3/27) -> 0.073252235 | P11: =(ftyp^2*H11^2/(4*a_2^2*c_2^2*(fsw*kHz)^2))+(b_2^3*ftyp*H11/(27*a_2^4*c_2*(fsw*kHz)))-(d_2^3*ftyp*H11/(27*a_2*c_2*(fsw*kHz)))+(b_2*d_2^2*ftyp*H11/(9*a_2^2*c_2*(fsw*kHz)))-(b_2^2*d_2*ftyp*H11/(9*a_2^3*c_2*(fsw*kHz))) -> #REF! | Q11: =(b_2*d_2^2/(9*a_2))-(b_2^2*d_2/(9*a_2^2))+(ftyp*H11/(2*a_2*c_2*(fsw*kHz))) -> #REF! | R11: =(d_2^2/9)+(b_2^2/(9*a_2^2))-(2*b_2*d_2/(9*a_2)) -> 0.067799508 | S11: =(b_2*c_2*(fsw*kHz)+2*a_2*c_2*d_2*(fsw*kHz))/(3*a_2*c_2*(fsw*kHz)) -> #REF! | T11: =((O11+SQRT(P11)+Q11)^(1/3))+(R11/((O11+SQRT(P11)+Q11)^(1/3)))+S11 -> #REF! | U11: =c_3+(SQRT(ftyp)*SQRT(H11)/(SQRT(a_3)*SQRT(b_3)*SQRT(fsw*kHz))) -> #REF! | V11: =(a_4*(fsw*kHz)*b_4/ftyp) -> #REF! | W11: =IF(I11>=0.5,IF(I11<1,I11,IF(N11>=1,IF(N11<2,N11,IF(T11>=2,IF(T11<4.5,T11,IF(U11>=4.5,IF(U11<4.6,U11,V11)))))))) -> #REF! | X11: =Pin_max/G11 -> #REF! | Y11: =-X11*Rsense*1.414 -> #REF! | Z11: =MIN(6,MAX(0.5,Beta*G*($Y11-Voff_trim)/(MAX(0,MIN(4.5,W11)-Alpha1_A)+MAX(0,MIN(4.5,W11)-Alpha1_B)-Alpha1_C)+Alpha2)) -> #REF!
A12: VCOMP1 | B12: =(1*10^-9*(5*10^8*SQRT(fsw*kHz)+(1.09655978*10^10)*SQRT(ftyp)*SQRT(B10)))/SQRT(fsw*kHz) -> #REF! | G12: =G11+1 -> #REF! | H12: =(Iout*(Vout_nom^2)*2.5*Rsense*K_1)/(eff*(G12^2)*K_FQ)*us -> #REF! | I12: =(1*10^-9*(5*10^8*SQRT(fsw*kHz)+(1.09655978*10^10)*SQRT(ftyp)*SQRT(H12)))/SQRT(fsw*kHz) -> #REF! | J12: =(b_1^3/(27*a_1^3))-(d_1^3/27)+SQRT((ftyp)^2*H12^2/(4*a_1^2*c_1^2*(fsw*kHz)^2))+(b_1^3*(ftyp)*H12/(27*a_1^4*c_1*(fsw*kHz))-(d_1^3*(ftyp)*H12/(27*a_1*c_1*(fsw*kHz)))+(b_1*d_1^2*(ftyp)*H12/(9*a_1^2*c_1*(fsw*kHz)))-(b_1^2*d_1*(ftyp)*H12/(9*a_1^3*c_1*(fsw*kHz)))) -> #REF! | K12: =(b_1*d_1^2/(9*a_1))-(b_1^2*d_1/(9*a_1^2))+(ftyp*H12/(2*a_1*c_1*fsw*kHz)) -> #REF! | L12: =(d_1^2/9)+(b_1^2/(9*a_1^2))-(2*b_1*d_1/(9*a_1)) -> 0.00045657097 | M12: =((b_1*c_1*fsw*kHz)+(2*a_1*c_1*d_1*fsw*kHz))/(3*a_1*c_1*fsw*kHz) -> #REF! | N12: =(J12+K12)^(1/3)+(L12/(J12^(1/3)))+M12 -> #REF! | O12: =(b_2^3/(27*a_2^3))-(d_2^3/27) -> 0.073252235 | P12: =(ftyp^2*H12^2/(4*a_2^2*c_2^2*(fsw*kHz)^2))+(b_2^3*ftyp*H12/(27*a_2^4*c_2*(fsw*kHz)))-(d_2^3*ftyp*H12/(27*a_2*c_2*(fsw*kHz)))+(b_2*d_2^2*ftyp*H12/(9*a_2^2*c_2*(fsw*kHz)))-(b_2^2*d_2*ftyp*H12/(9*a_2^3*c_2*(fsw*kHz))) -> #REF! | Q12: =(b_2*d_2^2/(9*a_2))-(b_2^2*d_2/(9*a_2^2))+(ftyp*H12/(2*a_2*c_2*(fsw*kHz))) -> #REF! | R12: =(d_2^2/9)+(b_2^2/(9*a_2^2))-(2*b_2*d_2/(9*a_2)) -> 0.067799508 | S12: =(b_2*c_2*(fsw*kHz)+2*a_2*c_2*d_2*(fsw*kHz))/(3*a_2*c_2*(fsw*kHz)) -> #REF! | T12: =((O12+SQRT(P12)+Q12)^(1/3))+(R12/((O12+SQRT(P12)+Q12)^(1/3)))+S12 -> #REF! | U12: =c_3+(SQRT(ftyp)*SQRT(H12)/(SQRT(a_3)*SQRT(b_3)*SQRT(fsw*kHz))) -> #REF! | V12: =(a_4*(fsw*kHz)*b_4/ftyp) -> #REF! | W12: =IF(I12>=0.5,IF(I12<1,I12,IF(N12>=1,IF(N12<2,N12,IF(T12>=2,IF(T12<4.5,T12,IF(U12>=4.5,IF(U12<4.6,U12,V12)))))))) -> #REF! | X12: =Pin_max/G12 -> #REF! | Y12: =-X12*Rsense*1.414 -> #REF! | Z12: =MIN(6,MAX(0.5,Beta*G*($Y12-Voff_trim)/(MAX(0,MIN(4.5,W12)-Alpha1_A)+MAX(0,MIN(4.5,W12)-Alpha1_B)-Alpha1_C)+Alpha2)) -> #REF!
D13: VCOMP1 | E13: =(1*10^-9*(5*10^8*SQRT(fsw*kHz)+(1.09655978*10^10)*SQRT(ftyp)*SQRT(E11)))/SQRT(fsw*kHz) -> #REF! | G13: =G12+1 -> #REF! | H13: =(Iout*(Vout_nom^2)*2.5*Rsense*K_1)/(eff*(G13^2)*K_FQ)*us -> #REF! | I13: =(1*10^-9*(5*10^8*SQRT(fsw*kHz)+(1.09655978*10^10)*SQRT(ftyp)*SQRT(H13)))/SQRT(fsw*kHz) -> #REF! | J13: =(b_1^3/(27*a_1^3))-(d_1^3/27)+SQRT((ftyp)^2*H13^2/(4*a_1^2*c_1^2*(fsw*kHz)^2))+(b_1^3*(ftyp)*H13/(27*a_1^4*c_1*(fsw*kHz))-(d_1^3*(ftyp)*H13/(27*a_1*c_1*(fsw*kHz)))+(b_1*d_1^2*(ftyp)*H13/(9*a_1^2*c_1*(fsw*kHz)))-(b_1^2*d_1*(ftyp)*H13/(9*a_1^3*c_1*(fsw*kHz)))) -> #REF! | K13: =(b_1*d_1^2/(9*a_1))-(b_1^2*d_1/(9*a_1^2))+(ftyp*H13/(2*a_1*c_1*fsw*kHz)) -> #REF! | L13: =(d_1^2/9)+(b_1^2/(9*a_1^2))-(2*b_1*d_1/(9*a_1)) -> 0.00045657097 | M13: =((b_1*c_1*fsw*kHz)+(2*a_1*c_1*d_1*fsw*kHz))/(3*a_1*c_1*fsw*kHz) -> #REF! | N13: =(J13+K13)^(1/3)+(L13/(J13^(1/3)))+M13 -> #REF! | O13: =(b_2^3/(27*a_2^3))-(d_2^3/27) -> 0.073252235 | P13: =(ftyp^2*H13^2/(4*a_2^2*c_2^2*(fsw*kHz)^2))+(b_2^3*ftyp*H13/(27*a_2^4*c_2*(fsw*kHz)))-(d_2^3*ftyp*H13/(27*a_2*c_2*(fsw*kHz)))+(b_2*d_2^2*ftyp*H13/(9*a_2^2*c_2*(fsw*kHz)))-(b_2^2*d_2*ftyp*H13/(9*a_2^3*c_2*(fsw*kHz))) -> #REF! | Q13: =(b_2*d_2^2/(9*a_2))-(b_2^2*d_2/(9*a_2^2))+(ftyp*H13/(2*a_2*c_2*(fsw*kHz))) -> #REF! | R13: =(d_2^2/9)+(b_2^2/(9*a_2^2))-(2*b_2*d_2/(9*a_2)) -> 0.067799508 | S13: =(b_2*c_2*(fsw*kHz)+2*a_2*c_2*d_2*(fsw*kHz))/(3*a_2*c_2*(fsw*kHz)) -> #REF! | T13: =((O13+SQRT(P13)+Q13)^(1/3))+(R13/((O13+SQRT(P13)+Q13)^(1/3)))+S13 -> #REF! | U13: =c_3+(SQRT(ftyp)*SQRT(H13)/(SQRT(a_3)*SQRT(b_3)*SQRT(fsw*kHz))) -> #REF! | V13: =(a_4*(fsw*kHz)*b_4/ftyp) -> #REF! | W13: =IF(I13>=0.5,IF(I13<1,I13,IF(N13>=1,IF(N13<2,N13,IF(T13>=2,IF(T13<4.5,T13,IF(U13>=4.5,IF(U13<4.6,U13,V13)))))))) -> #REF! | X13: =Pin_max/G13 -> #REF! | Y13: =-X13*Rsense*1.414 -> #REF! | Z13: =MIN(6,MAX(0.5,Beta*G*($Y13-Voff_trim)/(MAX(0,MIN(4.5,W13)-Alpha1_A)+MAX(0,MIN(4.5,W13)-Alpha1_B)-Alpha1_C)+Alpha2)) -> #REF!
A14: a1 | B14: 0.156 | G14: =G13+1 -> #REF! | H14: =(Iout*(Vout_nom^2)*2.5*Rsense*K_1)/(eff*(G14^2)*K_FQ)*us -> #REF! | I14: =(1*10^-9*(5*10^8*SQRT(fsw*kHz)+(1.09655978*10^10)*SQRT(ftyp)*SQRT(H14)))/SQRT(fsw*kHz) -> #REF! | J14: =(b_1^3/(27*a_1^3))-(d_1^3/27)+SQRT((ftyp)^2*H14^2/(4*a_1^2*c_1^2*(fsw*kHz)^2))+(b_1^3*(ftyp)*H14/(27*a_1^4*c_1*(fsw*kHz))-(d_1^3*(ftyp)*H14/(27*a_1*c_1*(fsw*kHz)))+(b_1*d_1^2*(ftyp)*H14/(9*a_1^2*c_1*(fsw*kHz)))-(b_1^2*d_1*(ftyp)*H14/(9*a_1^3*c_1*(fsw*kHz)))) -> #REF! | K14: =(b_1*d_1^2/(9*a_1))-(b_1^2*d_1/(9*a_1^2))+(ftyp*H14/(2*a_1*c_1*fsw*kHz)) -> #REF! | L14: =(d_1^2/9)+(b_1^2/(9*a_1^2))-(2*b_1*d_1/(9*a_1)) -> 0.00045657097 | M14: =((b_1*c_1*fsw*kHz)+(2*a_1*c_1*d_1*fsw*kHz))/(3*a_1*c_1*fsw*kHz) -> #REF! | N14: =(J14+K14)^(1/3)+(L14/(J14^(1/3)))+M14 -> #REF! | O14: =(b_2^3/(27*a_2^3))-(d_2^3/27) -> 0.073252235 | P14: =(ftyp^2*H14^2/(4*a_2^2*c_2^2*(fsw*kHz)^2))+(b_2^3*ftyp*H14/(27*a_2^4*c_2*(fsw*kHz)))-(d_2^3*ftyp*H14/(27*a_2*c_2*(fsw*kHz)))+(b_2*d_2^2*ftyp*H14/(9*a_2^2*c_2*(fsw*kHz)))-(b_2^2*d_2*ftyp*H14/(9*a_2^3*c_2*(fsw*kHz))) -> #REF! | Q14: =(b_2*d_2^2/(9*a_2))-(b_2^2*d_2/(9*a_2^2))+(ftyp*H14/(2*a_2*c_2*(fsw*kHz))) -> #REF! | R14: =(d_2^2/9)+(b_2^2/(9*a_2^2))-(2*b_2*d_2/(9*a_2)) -> 0.067799508 | S14: =(b_2*c_2*(fsw*kHz)+2*a_2*c_2*d_2*(fsw*kHz))/(3*a_2*c_2*(fsw*kHz)) -> #REF! | T14: =((O14+SQRT(P14)+Q14)^(1/3))+(R14/((O14+SQRT(P14)+Q14)^(1/3)))+S14 -> #REF! | U14: =c_3+(SQRT(ftyp)*SQRT(H14)/(SQRT(a_3)*SQRT(b_3)*SQRT(fsw*kHz))) -> #REF! | V14: =(a_4*(fsw*kHz)*b_4/ftyp) -> #REF! | W14: =IF(I14>=0.5,IF(I14<1,I14,IF(N14>=1,IF(N14<2,N14,IF(T14>=2,IF(T14<4.5,T14,IF(U14>=4.5,IF(U14<4.6,U14,V14)))))))) -> #REF! | X14: =Pin_max/G14 -> #REF! | Y14: =-X14*Rsense*1.414 -> #REF! | Z14: =MIN(6,MAX(0.5,Beta*G*($Y14-Voff_trim)/(MAX(0,MIN(4.5,W14)-Alpha1_A)+MAX(0,MIN(4.5,W14)-Alpha1_B)-Alpha1_C)+Alpha2)) -> #REF!
A15: b1 | B15: 0.088 | D15: a1 | E15: 0.156 | G15: =G14+1 -> #REF! | H15: =(Iout*(Vout_nom^2)*2.5*Rsense*K_1)/(eff*(G15^2)*K_FQ)*us -> #REF! | I15: =(1*10^-9*(5*10^8*SQRT(fsw*kHz)+(1.09655978*10^10)*SQRT(ftyp)*SQRT(H15)))/SQRT(fsw*kHz) -> #REF! | J15: =(b_1^3/(27*a_1^3))-(d_1^3/27)+SQRT((ftyp)^2*H15^2/(4*a_1^2*c_1^2*(fsw*kHz)^2))+(b_1^3*(ftyp)*H15/(27*a_1^4*c_1*(fsw*kHz))-(d_1^3*(ftyp)*H15/(27*a_1*c_1*(fsw*kHz)))+(b_1*d_1^2*(ftyp)*H15/(9*a_1^2*c_1*(fsw*kHz)))-(b_1^2*d_1*(ftyp)*H15/(9*a_1^3*c_1*(fsw*kHz)))) -> #REF! | K15: =(b_1*d_1^2/(9*a_1))-(b_1^2*d_1/(9*a_1^2))+(ftyp*H15/(2*a_1*c_1*fsw*kHz)) -> #REF! | L15: =(d_1^2/9)+(b_1^2/(9*a_1^2))-(2*b_1*d_1/(9*a_1)) -> 0.00045657097 | M15: =((b_1*c_1*fsw*kHz)+(2*a_1*c_1*d_1*fsw*kHz))/(3*a_1*c_1*fsw*kHz) -> #REF! | N15: =(J15+K15)^(1/3)+(L15/(J15^(1/3)))+M15 -> #REF! | O15: =(b_2^3/(27*a_2^3))-(d_2^3/27) -> 0.073252235 | P15: =(ftyp^2*H15^2/(4*a_2^2*c_2^2*(fsw*kHz)^2))+(b_2^3*ftyp*H15/(27*a_2^4*c_2*(fsw*kHz)))-(d_2^3*ftyp*H15/(27*a_2*c_2*(fsw*kHz)))+(b_2*d_2^2*ftyp*H15/(9*a_2^2*c_2*(fsw*kHz)))-(b_2^2*d_2*ftyp*H15/(9*a_2^3*c_2*(fsw*kHz))) -> #REF! | Q15: =(b_2*d_2^2/(9*a_2))-(b_2^2*d_2/(9*a_2^2))+(ftyp*H15/(2*a_2*c_2*(fsw*kHz))) -> #REF! | R15: =(d_2^2/9)+(b_2^2/(9*a_2^2))-(2*b_2*d_2/(9*a_2)) -> 0.067799508 | S15: =(b_2*c_2*(fsw*kHz)+2*a_2*c_2*d_2*(fsw*kHz))/(3*a_2*c_2*(fsw*kHz)) -> #REF! | T15: =((O15+SQRT(P15)+Q15)^(1/3))+(R15/((O15+SQRT(P15)+Q15)^(1/3)))+S15 -> #REF! | U15: =c_3+(SQRT(ftyp)*SQRT(H15)/(SQRT(a_3)*SQRT(b_3)*SQRT(fsw*kHz))) -> #REF! | V15: =(a_4*(fsw*kHz)*b_4/ftyp) -> #REF! | W15: =IF(I15>=0.5,IF(I15<1,I15,IF(N15>=1,IF(N15<2,N15,IF(T15>=2,IF(T15<4.5,T15,IF(U15>=4.5,IF(U15<4.6,U15,V15)))))))) -> #REF! | X15: =Pin_max/G15 -> #REF! | Y15: =-X15*Rsense*1.414 -> #REF! | Z15: =MIN(6,MAX(0.5,Beta*G*($Y15-Voff_trim)/(MAX(0,MIN(4.5,W15)-Alpha1_A)+MAX(0,MIN(4.5,W15)-Alpha1_B)-Alpha1_C)+Alpha2)) -> #REF!
A16: c1 | B16: 0.1223 | D16: b1 | E16: 0.088 | G16: =G15+1 -> #REF! | H16: =(Iout*(Vout_nom^2)*2.5*Rsense*K_1)/(eff*(G16^2)*K_FQ)*us -> #REF! | I16: =(1*10^-9*(5*10^8*SQRT(fsw*kHz)+(1.09655978*10^10)*SQRT(ftyp)*SQRT(H16)))/SQRT(fsw*kHz) -> #REF! | J16: =(b_1^3/(27*a_1^3))-(d_1^3/27)+SQRT((ftyp)^2*H16^2/(4*a_1^2*c_1^2*(fsw*kHz)^2))+(b_1^3*(ftyp)*H16/(27*a_1^4*c_1*(fsw*kHz))-(d_1^3*(ftyp)*H16/(27*a_1*c_1*(fsw*kHz)))+(b_1*d_1^2*(ftyp)*H16/(9*a_1^2*c_1*(fsw*kHz)))-(b_1^2*d_1*(ftyp)*H16/(9*a_1^3*c_1*(fsw*kHz)))) -> #REF! | K16: =(b_1*d_1^2/(9*a_1))-(b_1^2*d_1/(9*a_1^2))+(ftyp*H16/(2*a_1*c_1*fsw*kHz)) -> #REF! | L16: =(d_1^2/9)+(b_1^2/(9*a_1^2))-(2*b_1*d_1/(9*a_1)) -> 0.00045657097 | M16: =((b_1*c_1*fsw*kHz)+(2*a_1*c_1*d_1*fsw*kHz))/(3*a_1*c_1*fsw*kHz) -> #REF! | N16: =(J16+K16)^(1/3)+(L16/(J16^(1/3)))+M16 -> #REF! | O16: =(b_2^3/(27*a_2^3))-(d_2^3/27) -> 0.073252235 | P16: =(ftyp^2*H16^2/(4*a_2^2*c_2^2*(fsw*kHz)^2))+(b_2^3*ftyp*H16/(27*a_2^4*c_2*(fsw*kHz)))-(d_2^3*ftyp*H16/(27*a_2*c_2*(fsw*kHz)))+(b_2*d_2^2*ftyp*H16/(9*a_2^2*c_2*(fsw*kHz)))-(b_2^2*d_2*ftyp*H16/(9*a_2^3*c_2*(fsw*kHz))) -> #REF! | Q16: =(b_2*d_2^2/(9*a_2))-(b_2^2*d_2/(9*a_2^2))+(ftyp*H16/(2*a_2*c_2*(fsw*kHz))) -> #REF! | R16: =(d_2^2/9)+(b_2^2/(9*a_2^2))-(2*b_2*d_2/(9*a_2)) -> 0.067799508 | S16: =(b_2*c_2*(fsw*kHz)+2*a_2*c_2*d_2*(fsw*kHz))/(3*a_2*c_2*(fsw*kHz)) -> #REF! | T16: =((O16+SQRT(P16)+Q16)^(1/3))+(R16/((O16+SQRT(P16)+Q16)^(1/3)))+S16 -> #REF! | U16: =c_3+(SQRT(ftyp)*SQRT(H16)/(SQRT(a_3)*SQRT(b_3)*SQRT(fsw*kHz))) -> #REF! | V16: =(a_4*(fsw*kHz)*b_4/ftyp) -> #REF! | W16: =IF(I16>=0.5,IF(I16<1,I16,IF(N16>=1,IF(N16<2,N16,IF(T16>=2,IF(T16<4.5,T16,IF(U16>=4.5,IF(U16<4.6,U16,V16)))))))) -> #REF! | X16: =Pin_max/G16 -> #REF! | Y16: =-X16*Rsense*1.414 -> #REF! | Z16: =MIN(6,MAX(0.5,Beta*G*($Y16-Voff_trim)/(MAX(0,MIN(4.5,W16)-Alpha1_A)+MAX(0,MIN(4.5,W16)-Alpha1_B)-Alpha1_C)+Alpha2)) -> #REF!
A17: d1 | B17: 0.5 | D17: c1 | E17: 0.1223 | G17: =G16+1 -> #REF! | H17: =(Iout*(Vout_nom^2)*2.5*Rsense*K_1)/(eff*(G17^2)*K_FQ)*us -> #REF! | I17: =(1*10^-9*(5*10^8*SQRT(fsw*kHz)+(1.09655978*10^10)*SQRT(ftyp)*SQRT(H17)))/SQRT(fsw*kHz) -> #REF! | J17: =(b_1^3/(27*a_1^3))-(d_1^3/27)+SQRT((ftyp)^2*H17^2/(4*a_1^2*c_1^2*(fsw*kHz)^2))+(b_1^3*(ftyp)*H17/(27*a_1^4*c_1*(fsw*kHz))-(d_1^3*(ftyp)*H17/(27*a_1*c_1*(fsw*kHz)))+(b_1*d_1^2*(ftyp)*H17/(9*a_1^2*c_1*(fsw*kHz)))-(b_1^2*d_1*(ftyp)*H17/(9*a_1^3*c_1*(fsw*kHz)))) -> #REF! | K17: =(b_1*d_1^2/(9*a_1))-(b_1^2*d_1/(9*a_1^2))+(ftyp*H17/(2*a_1*c_1*fsw*kHz)) -> #REF! | L17: =(d_1^2/9)+(b_1^2/(9*a_1^2))-(2*b_1*d_1/(9*a_1)) -> 0.00045657097 | M17: =((b_1*c_1*fsw*kHz)+(2*a_1*c_1*d_1*fsw*kHz))/(3*a_1*c_1*fsw*kHz) -> #REF! | N17: =(J17+K17)^(1/3)+(L17/(J17^(1/3)))+M17 -> #REF! | O17: =(b_2^3/(27*a_2^3))-(d_2^3/27) -> 0.073252235 | P17: =(ftyp^2*H17^2/(4*a_2^2*c_2^2*(fsw*kHz)^2))+(b_2^3*ftyp*H17/(27*a_2^4*c_2*(fsw*kHz)))-(d_2^3*ftyp*H17/(27*a_2*c_2*(fsw*kHz)))+(b_2*d_2^2*ftyp*H17/(9*a_2^2*c_2*(fsw*kHz)))-(b_2^2*d_2*ftyp*H17/(9*a_2^3*c_2*(fsw*kHz))) -> #REF! | Q17: =(b_2*d_2^2/(9*a_2))-(b_2^2*d_2/(9*a_2^2))+(ftyp*H17/(2*a_2*c_2*(fsw*kHz))) -> #REF! | R17: =(d_2^2/9)+(b_2^2/(9*a_2^2))-(2*b_2*d_2/(9*a_2)) -> 0.067799508 | S17: =(b_2*c_2*(fsw*kHz)+2*a_2*c_2*d_2*(fsw*kHz))/(3*a_2*c_2*(fsw*kHz)) -> #REF! | T17: =((O17+SQRT(P17)+Q17)^(1/3))+(R17/((O17+SQRT(P17)+Q17)^(1/3)))+S17 -> #REF! | U17: =c_3+(SQRT(ftyp)*SQRT(H17)/(SQRT(a_3)*SQRT(b_3)*SQRT(fsw*kHz))) -> #REF! | V17: =(a_4*(fsw*kHz)*b_4/ftyp) -> #REF! | W17: =IF(I17>=0.5,IF(I17<1,I17,IF(N17>=1,IF(N17<2,N17,IF(T17>=2,IF(T17<4.5,T17,IF(U17>=4.5,IF(U17<4.6,U17,V17)))))))) -> #REF! | X17: =Pin_max/G17 -> #REF! | Y17: =-X17*Rsense*1.414 -> #REF! | Z17: =MIN(6,MAX(0.5,Beta*G*($Y17-Voff_trim)/(MAX(0,MIN(4.5,W17)-Alpha1_A)+MAX(0,MIN(4.5,W17)-Alpha1_B)-Alpha1_C)+Alpha2)) -> #REF!
A18: K1V2 | B18: =(b_1^3/(27*a_1^3))-(d_1^3/27)+SQRT((ftyp)^2*B10^2/(4*a_1^2*c_1^2*(fsw*kHz)^2))+(b_1^3*(ftyp)*B10/(27*a_1^4*c_1*(fsw*kHz))-(d_1^3*(ftyp)*B10/(27*a_1*c_1*(fsw*kHz)))+(b_1*d_1^2*(ftyp)*B10/(9*a_1^2*c_1*(fsw*kHz)))-(b_1^2*d_1*(ftyp)*B10/(9*a_1^3*c_1*(fsw*kHz)))) -> #REF! | D18: d1 | E18: 0.5 | G18: =G17+1 -> #REF! | H18: =(Iout*(Vout_nom^2)*2.5*Rsense*K_1)/(eff*(G18^2)*K_FQ)*us -> #REF! | I18: =(1*10^-9*(5*10^8*SQRT(fsw*kHz)+(1.09655978*10^10)*SQRT(ftyp)*SQRT(H18)))/SQRT(fsw*kHz) -> #REF! | J18: =(b_1^3/(27*a_1^3))-(d_1^3/27)+SQRT((ftyp)^2*H18^2/(4*a_1^2*c_1^2*(fsw*kHz)^2))+(b_1^3*(ftyp)*H18/(27*a_1^4*c_1*(fsw*kHz))-(d_1^3*(ftyp)*H18/(27*a_1*c_1*(fsw*kHz)))+(b_1*d_1^2*(ftyp)*H18/(9*a_1^2*c_1*(fsw*kHz)))-(b_1^2*d_1*(ftyp)*H18/(9*a_1^3*c_1*(fsw*kHz)))) -> #REF! | K18: =(b_1*d_1^2/(9*a_1))-(b_1^2*d_1/(9*a_1^2))+(ftyp*H18/(2*a_1*c_1*fsw*kHz)) -> #REF! | L18: =(d_1^2/9)+(b_1^2/(9*a_1^2))-(2*b_1*d_1/(9*a_1)) -> 0.00045657097 | M18: =((b_1*c_1*fsw*kHz)+(2*a_1*c_1*d_1*fsw*kHz))/(3*a_1*c_1*fsw*kHz) -> #REF! | N18: =(J18+K18)^(1/3)+(L18/(J18^(1/3)))+M18 -> #REF! | O18: =(b_2^3/(27*a_2^3))-(d_2^3/27) -> 0.073252235 | P18: =(ftyp^2*H18^2/(4*a_2^2*c_2^2*(fsw*kHz)^2))+(b_2^3*ftyp*H18/(27*a_2^4*c_2*(fsw*kHz)))-(d_2^3*ftyp*H18/(27*a_2*c_2*(fsw*kHz)))+(b_2*d_2^2*ftyp*H18/(9*a_2^2*c_2*(fsw*kHz)))-(b_2^2*d_2*ftyp*H18/(9*a_2^3*c_2*(fsw*kHz))) -> #REF! | Q18: =(b_2*d_2^2/(9*a_2))-(b_2^2*d_2/(9*a_2^2))+(ftyp*H18/(2*a_2*c_2*(fsw*kHz))) -> #REF! | R18: =(d_2^2/9)+(b_2^2/(9*a_2^2))-(2*b_2*d_2/(9*a_2)) -> 0.067799508 | S18: =(b_2*c_2*(fsw*kHz)+2*a_2*c_2*d_2*(fsw*kHz))/(3*a_2*c_2*(fsw*kHz)) -> #REF! | T18: =((O18+SQRT(P18)+Q18)^(1/3))+(R18/((O18+SQRT(P18)+Q18)^(1/3)))+S18 -> #REF! | U18: =c_3+(SQRT(ftyp)*SQRT(H18)/(SQRT(a_3)*SQRT(b_3)*SQRT(fsw*kHz))) -> #REF! | V18: =(a_4*(fsw*kHz)*b_4/ftyp) -> #REF! | W18: =IF(I18>=0.5,IF(I18<1,I18,IF(N18>=1,IF(N18<2,N18,IF(T18>=2,IF(T18<4.5,T18,IF(U18>=4.5,IF(U18<4.6,U18,V18)))))))) -> #REF! | X18: =Pin_max/G18 -> #REF! | Y18: =-X18*Rsense*1.414 -> #REF! | Z18: =MIN(6,MAX(0.5,Beta*G*($Y18-Voff_trim)/(MAX(0,MIN(4.5,W18)-Alpha1_A)+MAX(0,MIN(4.5,W18)-Alpha1_B)-Alpha1_C)+Alpha2)) -> #REF!
A19: K2V2 | B19: =(b_1*d_1^2/(9*a_1))-(b_1^2*d_1/(9*a_1^2))+(ftyp*B10/(2*a_1*c_1*fsw*kHz)) -> #REF! | D19: K1V2 | E19: =(b_1^3/(27*a_1^3))-(d_1^3/27)+SQRT((ftyp)^2*E11^2/(4*a_1^2*c_1^2*(fsw*kHz)^2))+(b_1^3*(ftyp)*E11/(27*a_1^4*c_1*(fsw*kHz))-(d_1^3*(ftyp)*E11/(27*a_1*c_1*(fsw*kHz)))+(b_1*d_1^2*(ftyp)*E11/(9*a_1^2*c_1*(fsw*kHz)))-(b_1^2*d_1*(ftyp)*E11/(9*a_1^3*c_1*(fsw*kHz)))) -> #REF! | G19: =G18+1 -> #REF! | H19: =(Iout*(Vout_nom^2)*2.5*Rsense*K_1)/(eff*(G19^2)*K_FQ)*us -> #REF! | I19: =(1*10^-9*(5*10^8*SQRT(fsw*kHz)+(1.09655978*10^10)*SQRT(ftyp)*SQRT(H19)))/SQRT(fsw*kHz) -> #REF! | J19: =(b_1^3/(27*a_1^3))-(d_1^3/27)+SQRT((ftyp)^2*H19^2/(4*a_1^2*c_1^2*(fsw*kHz)^2))+(b_1^3*(ftyp)*H19/(27*a_1^4*c_1*(fsw*kHz))-(d_1^3*(ftyp)*H19/(27*a_1*c_1*(fsw*kHz)))+(b_1*d_1^2*(ftyp)*H19/(9*a_1^2*c_1*(fsw*kHz)))-(b_1^2*d_1*(ftyp)*H19/(9*a_1^3*c_1*(fsw*kHz)))) -> #REF! | K19: =(b_1*d_1^2/(9*a_1))-(b_1^2*d_1/(9*a_1^2))+(ftyp*H19/(2*a_1*c_1*fsw*kHz)) -> #REF! | L19: =(d_1^2/9)+(b_1^2/(9*a_1^2))-(2*b_1*d_1/(9*a_1)) -> 0.00045657097 | M19: =((b_1*c_1*fsw*kHz)+(2*a_1*c_1*d_1*fsw*kHz))/(3*a_1*c_1*fsw*kHz) -> #REF! | N19: =(J19+K19)^(1/3)+(L19/(J19^(1/3)))+M19 -> #REF! | O19: =(b_2^3/(27*a_2^3))-(d_2^3/27) -> 0.073252235 | P19: =(ftyp^2*H19^2/(4*a_2^2*c_2^2*(fsw*kHz)^2))+(b_2^3*ftyp*H19/(27*a_2^4*c_2*(fsw*kHz)))-(d_2^3*ftyp*H19/(27*a_2*c_2*(fsw*kHz)))+(b_2*d_2^2*ftyp*H19/(9*a_2^2*c_2*(fsw*kHz)))-(b_2^2*d_2*ftyp*H19/(9*a_2^3*c_2*(fsw*kHz))) -> #REF! | Q19: =(b_2*d_2^2/(9*a_2))-(b_2^2*d_2/(9*a_2^2))+(ftyp*H19/(2*a_2*c_2*(fsw*kHz))) -> #REF! | R19: =(d_2^2/9)+(b_2^2/(9*a_2^2))-(2*b_2*d_2/(9*a_2)) -> 0.067799508 | S19: =(b_2*c_2*(fsw*kHz)+2*a_2*c_2*d_2*(fsw*kHz))/(3*a_2*c_2*(fsw*kHz)) -> #REF! | T19: =((O19+SQRT(P19)+Q19)^(1/3))+(R19/((O19+SQRT(P19)+Q19)^(1/3)))+S19 -> #REF! | U19: =c_3+(SQRT(ftyp)*SQRT(H19)/(SQRT(a_3)*SQRT(b_3)*SQRT(fsw*kHz))) -> #REF! | V19: =(a_4*(fsw*kHz)*b_4/ftyp) -> #REF! | W19: =IF(I19>=0.5,IF(I19<1,I19,IF(N19>=1,IF(N19<2,N19,IF(T19>=2,IF(T19<4.5,T19,IF(U19>=4.5,IF(U19<4.6,U19,V19)))))))) -> #REF! | X19: =Pin_max/G19 -> #REF! | Y19: =-X19*Rsense*1.414 -> #REF! | Z19: =MIN(6,MAX(0.5,Beta*G*($Y19-Voff_trim)/(MAX(0,MIN(4.5,W19)-Alpha1_A)+MAX(0,MIN(4.5,W19)-Alpha1_B)-Alpha1_C)+Alpha2)) -> #REF!
A20: K3V2 | B20: =(d_1^2/9)+(b_1^2/(9*a_1^2))-(2*b_1*d_1/(9*a_1)) -> 0.00045657097 | D20: K2V2 | E20: =(b_1*d_1^2/(9*a_1))-(b_1^2*d_1/(9*a_1^2))+(ftyp*E11/(2*a_1*c_1*fsw*kHz)) -> #REF! | G20: =G19+1 -> #REF! | H20: =(Iout*(Vout_nom^2)*2.5*Rsense*K_1)/(eff*(G20^2)*K_FQ)*us -> #REF! | I20: =(1*10^-9*(5*10^8*SQRT(fsw*kHz)+(1.09655978*10^10)*SQRT(ftyp)*SQRT(H20)))/SQRT(fsw*kHz) -> #REF! | J20: =(b_1^3/(27*a_1^3))-(d_1^3/27)+SQRT((ftyp)^2*H20^2/(4*a_1^2*c_1^2*(fsw*kHz)^2))+(b_1^3*(ftyp)*H20/(27*a_1^4*c_1*(fsw*kHz))-(d_1^3*(ftyp)*H20/(27*a_1*c_1*(fsw*kHz)))+(b_1*d_1^2*(ftyp)*H20/(9*a_1^2*c_1*(fsw*kHz)))-(b_1^2*d_1*(ftyp)*H20/(9*a_1^3*c_1*(fsw*kHz)))) -> #REF! | K20: =(b_1*d_1^2/(9*a_1))-(b_1^2*d_1/(9*a_1^2))+(ftyp*H20/(2*a_1*c_1*fsw*kHz)) -> #REF! | L20: =(d_1^2/9)+(b_1^2/(9*a_1^2))-(2*b_1*d_1/(9*a_1)) -> 0.00045657097 | M20: =((b_1*c_1*fsw*kHz)+(2*a_1*c_1*d_1*fsw*kHz))/(3*a_1*c_1*fsw*kHz) -> #REF! | N20: =(J20+K20)^(1/3)+(L20/(J20^(1/3)))+M20 -> #REF! | O20: =(b_2^3/(27*a_2^3))-(d_2^3/27) -> 0.073252235 | P20: =(ftyp^2*H20^2/(4*a_2^2*c_2^2*(fsw*kHz)^2))+(b_2^3*ftyp*H20/(27*a_2^4*c_2*(fsw*kHz)))-(d_2^3*ftyp*H20/(27*a_2*c_2*(fsw*kHz)))+(b_2*d_2^2*ftyp*H20/(9*a_2^2*c_2*(fsw*kHz)))-(b_2^2*d_2*ftyp*H20/(9*a_2^3*c_2*(fsw*kHz))) -> #REF! | Q20: =(b_2*d_2^2/(9*a_2))-(b_2^2*d_2/(9*a_2^2))+(ftyp*H20/(2*a_2*c_2*(fsw*kHz))) -> #REF! | R20: =(d_2^2/9)+(b_2^2/(9*a_2^2))-(2*b_2*d_2/(9*a_2)) -> 0.067799508 | S20: =(b_2*c_2*(fsw*kHz)+2*a_2*c_2*d_2*(fsw*kHz))/(3*a_2*c_2*(fsw*kHz)) -> #REF! | T20: =((O20+SQRT(P20)+Q20)^(1/3))+(R20/((O20+SQRT(P20)+Q20)^(1/3)))+S20 -> #REF! | U20: =c_3+(SQRT(ftyp)*SQRT(H20)/(SQRT(a_3)*SQRT(b_3)*SQRT(fsw*kHz))) -> #REF! | V20: =(a_4*(fsw*kHz)*b_4/ftyp) -> #REF! | W20: =IF(I20>=0.5,IF(I20<1,I20,IF(N20>=1,IF(N20<2,N20,IF(T20>=2,IF(T20<4.5,T20,IF(U20>=4.5,IF(U20<4.6,U20,V20)))))))) -> #REF! | X20: =Pin_max/G20 -> #REF! | Y20: =-X20*Rsense*1.414 -> #REF! | Z20: =MIN(6,MAX(0.5,Beta*G*($Y20-Voff_trim)/(MAX(0,MIN(4.5,W20)-Alpha1_A)+MAX(0,MIN(4.5,W20)-Alpha1_B)-Alpha1_C)+Alpha2)) -> #REF!
A21: K4V2 | B21: =((b_1*c_1*fsw*kHz)+(2*a_1*c_1*d_1*fsw*kHz))/(3*a_1*c_1*fsw*kHz) -> #REF! | D21: K3V2 | E21: =(d_1^2/9)+(b_1^2/(9*a_1^2))-(2*b_1*d_1/(9*a_1)) -> 0.00045657097 | G21: =G20+1 -> #REF! | H21: =(Iout*(Vout_nom^2)*2.5*Rsense*K_1)/(eff*(G21^2)*K_FQ)*us -> #REF! | I21: =(1*10^-9*(5*10^8*SQRT(fsw*kHz)+(1.09655978*10^10)*SQRT(ftyp)*SQRT(H21)))/SQRT(fsw*kHz) -> #REF! | J21: =(b_1^3/(27*a_1^3))-(d_1^3/27)+SQRT((ftyp)^2*H21^2/(4*a_1^2*c_1^2*(fsw*kHz)^2))+(b_1^3*(ftyp)*H21/(27*a_1^4*c_1*(fsw*kHz))-(d_1^3*(ftyp)*H21/(27*a_1*c_1*(fsw*kHz)))+(b_1*d_1^2*(ftyp)*H21/(9*a_1^2*c_1*(fsw*kHz)))-(b_1^2*d_1*(ftyp)*H21/(9*a_1^3*c_1*(fsw*kHz)))) -> #REF! | K21: =(b_1*d_1^2/(9*a_1))-(b_1^2*d_1/(9*a_1^2))+(ftyp*H21/(2*a_1*c_1*fsw*kHz)) -> #REF! | L21: =(d_1^2/9)+(b_1^2/(9*a_1^2))-(2*b_1*d_1/(9*a_1)) -> 0.00045657097 | M21: =((b_1*c_1*fsw*kHz)+(2*a_1*c_1*d_1*fsw*kHz))/(3*a_1*c_1*fsw*kHz) -> #REF! | N21: =(J21+K21)^(1/3)+(L21/(J21^(1/3)))+M21 -> #REF! | O21: =(b_2^3/(27*a_2^3))-(d_2^3/27) -> 0.073252235 | P21: =(ftyp^2*H21^2/(4*a_2^2*c_2^2*(fsw*kHz)^2))+(b_2^3*ftyp*H21/(27*a_2^4*c_2*(fsw*kHz)))-(d_2^3*ftyp*H21/(27*a_2*c_2*(fsw*kHz)))+(b_2*d_2^2*ftyp*H21/(9*a_2^2*c_2*(fsw*kHz)))-(b_2^2*d_2*ftyp*H21/(9*a_2^3*c_2*(fsw*kHz))) -> #REF! | Q21: =(b_2*d_2^2/(9*a_2))-(b_2^2*d_2/(9*a_2^2))+(ftyp*H21/(2*a_2*c_2*(fsw*kHz))) -> #REF! | R21: =(d_2^2/9)+(b_2^2/(9*a_2^2))-(2*b_2*d_2/(9*a_2)) -> 0.067799508 | S21: =(b_2*c_2*(fsw*kHz)+2*a_2*c_2*d_2*(fsw*kHz))/(3*a_2*c_2*(fsw*kHz)) -> #REF! | T21: =((O21+SQRT(P21)+Q21)^(1/3))+(R21/((O21+SQRT(P21)+Q21)^(1/3)))+S21 -> #REF! | U21: =c_3+(SQRT(ftyp)*SQRT(H21)/(SQRT(a_3)*SQRT(b_3)*SQRT(fsw*kHz))) -> #REF! | V21: =(a_4*(fsw*kHz)*b_4/ftyp) -> #REF! | W21: =IF(I21>=0.5,IF(I21<1,I21,IF(N21>=1,IF(N21<2,N21,IF(T21>=2,IF(T21<4.5,T21,IF(U21>=4.5,IF(U21<4.6,U21,V21)))))))) -> #REF! | X21: =Pin_max/G21 -> #REF! | Y21: =-X21*Rsense*1.414 -> #REF! | Z21: =MIN(6,MAX(0.5,Beta*G*($Y21-Voff_trim)/(MAX(0,MIN(4.5,W21)-Alpha1_A)+MAX(0,MIN(4.5,W21)-Alpha1_B)-Alpha1_C)+Alpha2)) -> #REF!
A22: VCOMP2 | B22: =(B18+B19)^(1/3)+(B20/(B18^(1/3)))+B21 -> #REF! | D22: K4V2 | E22: =((b_1*c_1*fsw*kHz)+(2*a_1*c_1*d_1*fsw*kHz))/(3*a_1*c_1*fsw*kHz) -> #REF! | G22: =G21+1 -> #REF! | H22: =(Iout*(Vout_nom^2)*2.5*Rsense*K_1)/(eff*(G22^2)*K_FQ)*us -> #REF! | I22: =(1*10^-9*(5*10^8*SQRT(fsw*kHz)+(1.09655978*10^10)*SQRT(ftyp)*SQRT(H22)))/SQRT(fsw*kHz) -> #REF! | J22: =(b_1^3/(27*a_1^3))-(d_1^3/27)+SQRT((ftyp)^2*H22^2/(4*a_1^2*c_1^2*(fsw*kHz)^2))+(b_1^3*(ftyp)*H22/(27*a_1^4*c_1*(fsw*kHz))-(d_1^3*(ftyp)*H22/(27*a_1*c_1*(fsw*kHz)))+(b_1*d_1^2*(ftyp)*H22/(9*a_1^2*c_1*(fsw*kHz)))-(b_1^2*d_1*(ftyp)*H22/(9*a_1^3*c_1*(fsw*kHz)))) -> #REF! | K22: =(b_1*d_1^2/(9*a_1))-(b_1^2*d_1/(9*a_1^2))+(ftyp*H22/(2*a_1*c_1*fsw*kHz)) -> #REF! | L22: =(d_1^2/9)+(b_1^2/(9*a_1^2))-(2*b_1*d_1/(9*a_1)) -> 0.00045657097 | M22: =((b_1*c_1*fsw*kHz)+(2*a_1*c_1*d_1*fsw*kHz))/(3*a_1*c_1*fsw*kHz) -> #REF! | N22: =(J22+K22)^(1/3)+(L22/(J22^(1/3)))+M22 -> #REF! | O22: =(b_2^3/(27*a_2^3))-(d_2^3/27) -> 0.073252235 | P22: =(ftyp^2*H22^2/(4*a_2^2*c_2^2*(fsw*kHz)^2))+(b_2^3*ftyp*H22/(27*a_2^4*c_2*(fsw*kHz)))-(d_2^3*ftyp*H22/(27*a_2*c_2*(fsw*kHz)))+(b_2*d_2^2*ftyp*H22/(9*a_2^2*c_2*(fsw*kHz)))-(b_2^2*d_2*ftyp*H22/(9*a_2^3*c_2*(fsw*kHz))) -> #REF! | Q22: =(b_2*d_2^2/(9*a_2))-(b_2^2*d_2/(9*a_2^2))+(ftyp*H22/(2*a_2*c_2*(fsw*kHz))) -> #REF! | R22: =(d_2^2/9)+(b_2^2/(9*a_2^2))-(2*b_2*d_2/(9*a_2)) -> 0.067799508 | S22: =(b_2*c_2*(fsw*kHz)+2*a_2*c_2*d_2*(fsw*kHz))/(3*a_2*c_2*(fsw*kHz)) -> #REF! | T22: =((O22+SQRT(P22)+Q22)^(1/3))+(R22/((O22+SQRT(P22)+Q22)^(1/3)))+S22 -> #REF! | U22: =c_3+(SQRT(ftyp)*SQRT(H22)/(SQRT(a_3)*SQRT(b_3)*SQRT(fsw*kHz))) -> #REF! | V22: =(a_4*(fsw*kHz)*b_4/ftyp) -> #REF! | W22: =IF(I22>=0.5,IF(I22<1,I22,IF(N22>=1,IF(N22<2,N22,IF(T22>=2,IF(T22<4.5,T22,IF(U22>=4.5,IF(U22<4.6,U22,V22)))))))) -> #REF! | X22: =Pin_max/G22 -> #REF! | Y22: =-X22*Rsense*1.414 -> #REF! | Z22: =MIN(6,MAX(0.5,Beta*G*($Y22-Voff_trim)/(MAX(0,MIN(4.5,W22)-Alpha1_A)+MAX(0,MIN(4.5,W22)-Alpha1_B)-Alpha1_C)+Alpha2)) -> #REF!
D23: VCOMP2 | E23: =(E19+E20)^(1/3)+(E21/(E19^(1/3)))+E22 -> #REF! | G23: =G22+1 -> #REF! | H23: =(Iout*(Vout_nom^2)*2.5*Rsense*K_1)/(eff*(G23^2)*K_FQ)*us -> #REF! | I23: =(1*10^-9*(5*10^8*SQRT(fsw*kHz)+(1.09655978*10^10)*SQRT(ftyp)*SQRT(H23)))/SQRT(fsw*kHz) -> #REF! | J23: =(b_1^3/(27*a_1^3))-(d_1^3/27)+SQRT((ftyp)^2*H23^2/(4*a_1^2*c_1^2*(fsw*kHz)^2))+(b_1^3*(ftyp)*H23/(27*a_1^4*c_1*(fsw*kHz))-(d_1^3*(ftyp)*H23/(27*a_1*c_1*(fsw*kHz)))+(b_1*d_1^2*(ftyp)*H23/(9*a_1^2*c_1*(fsw*kHz)))-(b_1^2*d_1*(ftyp)*H23/(9*a_1^3*c_1*(fsw*kHz)))) -> #REF! | K23: =(b_1*d_1^2/(9*a_1))-(b_1^2*d_1/(9*a_1^2))+(ftyp*H23/(2*a_1*c_1*fsw*kHz)) -> #REF! | L23: =(d_1^2/9)+(b_1^2/(9*a_1^2))-(2*b_1*d_1/(9*a_1)) -> 0.00045657097 | M23: =((b_1*c_1*fsw*kHz)+(2*a_1*c_1*d_1*fsw*kHz))/(3*a_1*c_1*fsw*kHz) -> #REF! | N23: =(J23+K23)^(1/3)+(L23/(J23^(1/3)))+M23 -> #REF! | O23: =(b_2^3/(27*a_2^3))-(d_2^3/27) -> 0.073252235 | P23: =(ftyp^2*H23^2/(4*a_2^2*c_2^2*(fsw*kHz)^2))+(b_2^3*ftyp*H23/(27*a_2^4*c_2*(fsw*kHz)))-(d_2^3*ftyp*H23/(27*a_2*c_2*(fsw*kHz)))+(b_2*d_2^2*ftyp*H23/(9*a_2^2*c_2*(fsw*kHz)))-(b_2^2*d_2*ftyp*H23/(9*a_2^3*c_2*(fsw*kHz))) -> #REF! | Q23: =(b_2*d_2^2/(9*a_2))-(b_2^2*d_2/(9*a_2^2))+(ftyp*H23/(2*a_2*c_2*(fsw*kHz))) -> #REF! | R23: =(d_2^2/9)+(b_2^2/(9*a_2^2))-(2*b_2*d_2/(9*a_2)) -> 0.067799508 | S23: =(b_2*c_2*(fsw*kHz)+2*a_2*c_2*d_2*(fsw*kHz))/(3*a_2*c_2*(fsw*kHz)) -> #REF! | T23: =((O23+SQRT(P23)+Q23)^(1/3))+(R23/((O23+SQRT(P23)+Q23)^(1/3)))+S23 -> #REF! | U23: =c_3+(SQRT(ftyp)*SQRT(H23)/(SQRT(a_3)*SQRT(b_3)*SQRT(fsw*kHz))) -> #REF! | V23: =(a_4*(fsw*kHz)*b_4/ftyp) -> #REF! | W23: =IF(I23>=0.5,IF(I23<1,I23,IF(N23>=1,IF(N23<2,N23,IF(T23>=2,IF(T23<4.5,T23,IF(U23>=4.5,IF(U23<4.6,U23,V23)))))))) -> #REF! | X23: =Pin_max/G23 -> #REF! | Y23: =-X23*Rsense*1.414 -> #REF! | Z23: =MIN(6,MAX(0.5,Beta*G*($Y23-Voff_trim)/(MAX(0,MIN(4.5,W23)-Alpha1_A)+MAX(0,MIN(4.5,W23)-Alpha1_B)-Alpha1_C)+Alpha2)) -> #REF!
A24: a2 | B24: 0.313 | G24: =G23+1 -> #REF! | H24: =(Iout*(Vout_nom^2)*2.5*Rsense*K_1)/(eff*(G24^2)*K_FQ)*us -> #REF! | I24: =(1*10^-9*(5*10^8*SQRT(fsw*kHz)+(1.09655978*10^10)*SQRT(ftyp)*SQRT(H24)))/SQRT(fsw*kHz) -> #REF! | J24: =(b_1^3/(27*a_1^3))-(d_1^3/27)+SQRT((ftyp)^2*H24^2/(4*a_1^2*c_1^2*(fsw*kHz)^2))+(b_1^3*(ftyp)*H24/(27*a_1^4*c_1*(fsw*kHz))-(d_1^3*(ftyp)*H24/(27*a_1*c_1*(fsw*kHz)))+(b_1*d_1^2*(ftyp)*H24/(9*a_1^2*c_1*(fsw*kHz)))-(b_1^2*d_1*(ftyp)*H24/(9*a_1^3*c_1*(fsw*kHz)))) -> #REF! | K24: =(b_1*d_1^2/(9*a_1))-(b_1^2*d_1/(9*a_1^2))+(ftyp*H24/(2*a_1*c_1*fsw*kHz)) -> #REF! | L24: =(d_1^2/9)+(b_1^2/(9*a_1^2))-(2*b_1*d_1/(9*a_1)) -> 0.00045657097 | M24: =((b_1*c_1*fsw*kHz)+(2*a_1*c_1*d_1*fsw*kHz))/(3*a_1*c_1*fsw*kHz) -> #REF! | N24: =(J24+K24)^(1/3)+(L24/(J24^(1/3)))+M24 -> #REF! | O24: =(b_2^3/(27*a_2^3))-(d_2^3/27) -> 0.073252235 | P24: =(ftyp^2*H24^2/(4*a_2^2*c_2^2*(fsw*kHz)^2))+(b_2^3*ftyp*H24/(27*a_2^4*c_2*(fsw*kHz)))-(d_2^3*ftyp*H24/(27*a_2*c_2*(fsw*kHz)))+(b_2*d_2^2*ftyp*H24/(9*a_2^2*c_2*(fsw*kHz)))-(b_2^2*d_2*ftyp*H24/(9*a_2^3*c_2*(fsw*kHz))) -> #REF! | Q24: =(b_2*d_2^2/(9*a_2))-(b_2^2*d_2/(9*a_2^2))+(ftyp*H24/(2*a_2*c_2*(fsw*kHz))) -> #REF! | R24: =(d_2^2/9)+(b_2^2/(9*a_2^2))-(2*b_2*d_2/(9*a_2)) -> 0.067799508 | S24: =(b_2*c_2*(fsw*kHz)+2*a_2*c_2*d_2*(fsw*kHz))/(3*a_2*c_2*(fsw*kHz)) -> #REF! | T24: =((O24+SQRT(P24)+Q24)^(1/3))+(R24/((O24+SQRT(P24)+Q24)^(1/3)))+S24 -> #REF! | U24: =c_3+(SQRT(ftyp)*SQRT(H24)/(SQRT(a_3)*SQRT(b_3)*SQRT(fsw*kHz))) -> #REF! | V24: =(a_4*(fsw*kHz)*b_4/ftyp) -> #REF! | W24: =IF(I24>=0.5,IF(I24<1,I24,IF(N24>=1,IF(N24<2,N24,IF(T24>=2,IF(T24<4.5,T24,IF(U24>=4.5,IF(U24<4.6,U24,V24)))))))) -> #REF! | X24: =Pin_max/G24 -> #REF! | Y24: =-X24*Rsense*1.414 -> #REF! | Z24: =MIN(6,MAX(0.5,Beta*G*($Y24-Voff_trim)/(MAX(0,MIN(4.5,W24)-Alpha1_A)+MAX(0,MIN(4.5,W24)-Alpha1_B)-Alpha1_C)+Alpha2)) -> #REF!
A25: b2 | B25: 0.401 | D25: a2 | E25: 0.313 | G25: =G24+1 -> #REF! | H25: =(Iout*(Vout_nom^2)*2.5*Rsense*K_1)/(eff*(G25^2)*K_FQ)*us -> #REF! | I25: =(1*10^-9*(5*10^8*SQRT(fsw*kHz)+(1.09655978*10^10)*SQRT(ftyp)*SQRT(H25)))/SQRT(fsw*kHz) -> #REF! | J25: =(b_1^3/(27*a_1^3))-(d_1^3/27)+SQRT((ftyp)^2*H25^2/(4*a_1^2*c_1^2*(fsw*kHz)^2))+(b_1^3*(ftyp)*H25/(27*a_1^4*c_1*(fsw*kHz))-(d_1^3*(ftyp)*H25/(27*a_1*c_1*(fsw*kHz)))+(b_1*d_1^2*(ftyp)*H25/(9*a_1^2*c_1*(fsw*kHz)))-(b_1^2*d_1*(ftyp)*H25/(9*a_1^3*c_1*(fsw*kHz)))) -> #REF! | K25: =(b_1*d_1^2/(9*a_1))-(b_1^2*d_1/(9*a_1^2))+(ftyp*H25/(2*a_1*c_1*fsw*kHz)) -> #REF! | L25: =(d_1^2/9)+(b_1^2/(9*a_1^2))-(2*b_1*d_1/(9*a_1)) -> 0.00045657097 | M25: =((b_1*c_1*fsw*kHz)+(2*a_1*c_1*d_1*fsw*kHz))/(3*a_1*c_1*fsw*kHz) -> #REF! | N25: =(J25+K25)^(1/3)+(L25/(J25^(1/3)))+M25 -> #REF! | O25: =(b_2^3/(27*a_2^3))-(d_2^3/27) -> 0.073252235 | P25: =(ftyp^2*H25^2/(4*a_2^2*c_2^2*(fsw*kHz)^2))+(b_2^3*ftyp*H25/(27*a_2^4*c_2*(fsw*kHz)))-(d_2^3*ftyp*H25/(27*a_2*c_2*(fsw*kHz)))+(b_2*d_2^2*ftyp*H25/(9*a_2^2*c_2*(fsw*kHz)))-(b_2^2*d_2*ftyp*H25/(9*a_2^3*c_2*(fsw*kHz))) -> #REF! | Q25: =(b_2*d_2^2/(9*a_2))-(b_2^2*d_2/(9*a_2^2))+(ftyp*H25/(2*a_2*c_2*(fsw*kHz))) -> #REF! | R25: =(d_2^2/9)+(b_2^2/(9*a_2^2))-(2*b_2*d_2/(9*a_2)) -> 0.067799508 | S25: =(b_2*c_2*(fsw*kHz)+2*a_2*c_2*d_2*(fsw*kHz))/(3*a_2*c_2*(fsw*kHz)) -> #REF! | T25: =((O25+SQRT(P25)+Q25)^(1/3))+(R25/((O25+SQRT(P25)+Q25)^(1/3)))+S25 -> #REF! | U25: =c_3+(SQRT(ftyp)*SQRT(H25)/(SQRT(a_3)*SQRT(b_3)*SQRT(fsw*kHz))) -> #REF! | V25: =(a_4*(fsw*kHz)*b_4/ftyp) -> #REF! | W25: =IF(I25>=0.5,IF(I25<1,I25,IF(N25>=1,IF(N25<2,N25,IF(T25>=2,IF(T25<4.5,T25,IF(U25>=4.5,IF(U25<4.6,U25,V25)))))))) -> #REF! | X25: =Pin_max/G25 -> #REF! | Y25: =-X25*Rsense*1.414 -> #REF! | Z25: =MIN(6,MAX(0.5,Beta*G*($Y25-Voff_trim)/(MAX(0,MIN(4.5,W25)-Alpha1_A)+MAX(0,MIN(4.5,W25)-Alpha1_B)-Alpha1_C)+Alpha2)) -> #REF!
A26: c2 | B26: 0.1223 | D26: b2 | E26: 0.401 | G26: =G25+1 -> #REF! | H26: =(Iout*(Vout_nom^2)*2.5*Rsense*K_1)/(eff*(G26^2)*K_FQ)*us -> #REF! | I26: =(1*10^-9*(5*10^8*SQRT(fsw*kHz)+(1.09655978*10^10)*SQRT(ftyp)*SQRT(H26)))/SQRT(fsw*kHz) -> #REF! | J26: =(b_1^3/(27*a_1^3))-(d_1^3/27)+SQRT((ftyp)^2*H26^2/(4*a_1^2*c_1^2*(fsw*kHz)^2))+(b_1^3*(ftyp)*H26/(27*a_1^4*c_1*(fsw*kHz))-(d_1^3*(ftyp)*H26/(27*a_1*c_1*(fsw*kHz)))+(b_1*d_1^2*(ftyp)*H26/(9*a_1^2*c_1*(fsw*kHz)))-(b_1^2*d_1*(ftyp)*H26/(9*a_1^3*c_1*(fsw*kHz)))) -> #REF! | K26: =(b_1*d_1^2/(9*a_1))-(b_1^2*d_1/(9*a_1^2))+(ftyp*H26/(2*a_1*c_1*fsw*kHz)) -> #REF! | L26: =(d_1^2/9)+(b_1^2/(9*a_1^2))-(2*b_1*d_1/(9*a_1)) -> 0.00045657097 | M26: =((b_1*c_1*fsw*kHz)+(2*a_1*c_1*d_1*fsw*kHz))/(3*a_1*c_1*fsw*kHz) -> #REF! | N26: =(J26+K26)^(1/3)+(L26/(J26^(1/3)))+M26 -> #REF! | O26: =(b_2^3/(27*a_2^3))-(d_2^3/27) -> 0.073252235 | P26: =(ftyp^2*H26^2/(4*a_2^2*c_2^2*(fsw*kHz)^2))+(b_2^3*ftyp*H26/(27*a_2^4*c_2*(fsw*kHz)))-(d_2^3*ftyp*H26/(27*a_2*c_2*(fsw*kHz)))+(b_2*d_2^2*ftyp*H26/(9*a_2^2*c_2*(fsw*kHz)))-(b_2^2*d_2*ftyp*H26/(9*a_2^3*c_2*(fsw*kHz))) -> #REF! | Q26: =(b_2*d_2^2/(9*a_2))-(b_2^2*d_2/(9*a_2^2))+(ftyp*H26/(2*a_2*c_2*(fsw*kHz))) -> #REF! | R26: =(d_2^2/9)+(b_2^2/(9*a_2^2))-(2*b_2*d_2/(9*a_2)) -> 0.067799508 | S26: =(b_2*c_2*(fsw*kHz)+2*a_2*c_2*d_2*(fsw*kHz))/(3*a_2*c_2*(fsw*kHz)) -> #REF! | T26: =((O26+SQRT(P26)+Q26)^(1/3))+(R26/((O26+SQRT(P26)+Q26)^(1/3)))+S26 -> #REF! | U26: =c_3+(SQRT(ftyp)*SQRT(H26)/(SQRT(a_3)*SQRT(b_3)*SQRT(fsw*kHz))) -> #REF! | V26: =(a_4*(fsw*kHz)*b_4/ftyp) -> #REF! | W26: =IF(I26>=0.5,IF(I26<1,I26,IF(N26>=1,IF(N26<2,N26,IF(T26>=2,IF(T26<4.5,T26,IF(U26>=4.5,IF(U26<4.6,U26,V26)))))))) -> #REF! | X26: =Pin_max/G26 -> #REF! | Y26: =-X26*Rsense*1.414 -> #REF! | Z26: =MIN(6,MAX(0.5,Beta*G*($Y26-Voff_trim)/(MAX(0,MIN(4.5,W26)-Alpha1_A)+MAX(0,MIN(4.5,W26)-Alpha1_B)-Alpha1_C)+Alpha2)) -> #REF!
